Workbook

Sheet 说明
A1: 运气工程 ⑤ —— Slots 游戏 RTP 计算规则 · ④WILD篇
A3: 来源：知乎《Slots 游戏 RTP 计算规则 - ④WILD篇》 https://zhuanlan.zhihu.com/p/1941187040885585474
A4: 专栏：运气工程：Slots 数值研究所 https://zhuanlan.zhihu.com/c_1918334633642287500
A6: 页签
A7: · 滚轴与赔付：3 行 × 5 列 示例滚轴 / 图案次数 / 赔付表
A8: · RTP分解：把主游戏 RTP 拆成「普通符号 RTP + WILD 介入 RTP + WILD 图案 RTP」
A9: · 首列WILD：第 1 轴 WILD 覆盖率 w → 主游戏连线 RTP 的敏感性
A10: · 四类WILD：倍率 / 扩展 / 黏性 WILD 的计算模型（原文四类清单）
A12: 一、本篇目标
A13: 给出四类 WILD 的可落地计算方法（含公式 / Excel 思路）+ 易错点。
A14: 本篇会介绍一种 WILD 特殊出现规则，和三种特殊玩法 WILD 的 RTP 计算方式。
A15: （原文提示：首列 WILD 实际不属于「特殊 WILD 图案」的范畴）
... A67: 本簿依据该文正文摘要（「本篇目标：给出四类 WILD 的可落地计算方法（含公式/Excel 思路）+ 易错点」、

Sheet 滚轴与赔付
A1: 3 行 × 5 列 示例滚轴 / 图案次数 / 赔付表
A3: 【转轮表】每列 20 停（环绕带）—— 蓝字可改
A4: 位置 | B4: 轮1 | C4: 轮2 | D4: 轮3 | E4: 轮4 | F4: 轮5
A5: 1 | B5: K | C5: K | D5: K | E5: K | F5: K
A6: 2 | B6: Q | C6: K | D6: K | E6: K | F6: K
A7: 3 | B7: Q | C7: K | D7: K | E7: K | F7: K
A8: 4 | B8: Q | C8: W | D8: W | E8: W | F8: W
A9: 5 | B9: J | C9: Q | D9: Q | E9: Q | F9: Q
A10: 6 | B10: J | C10: Q | D10: Q | E10: Q | F10: Q
A11: 7 | B11: J | C11: Q | D11: Q | E11: Q | F11: Q
A12: 8 | B12: J | C12: J | D12: J | E12: J | F12: J
A13: 9 | B13: 10 | C13: J | D13: J | E13: J | F13: J
A14: 10 | B14: 10 | C14: J | D14: J | E14: J | F14: J
A15: 11 | B15: 10 | C15: J | D15: J | E15: J | F15: J
A16: 12 | B16: 10 | C16: J | D16: 10 | E16: 10 | F16: 10
A17: 13 | B17: 10 | C17: 10 | D17: 10 | E17: 10 | F17: 10
A18: 14 | B18: 9 | C18: 10 | D18: 10 | E18: 10 | F18: 10
A19: 15 | B19: 9 | C19: 10 | D19: 10 | E19: 10 | F19: 10
A20: 16 | B20: 9 | C20: 9 | D20: 9 | E20: 9 | F20: 9
A21: 17 | B21: 9 | C21: 9 | D21: 9 | E21: 9 | F21: 9
A22: 18 | B22: 9 | C22: 9 | D22: 9 | E22: 9 | F22: 9
A23: 19 | B23: 9 | C23: 9 | D23: 9 | E23: 9 | F23: 9
A24: 20 | B24: S | C24: S | D24: S | E24: S | F24: S
A25: 每轮格数 | B25: =COUNTA(B5:B24) -> 20 | C25: =COUNTA(C5:C24) -> 20 | D25: =COUNTA(D5:D24) -> 20 | E25: =COUNTA(E5:E24) -> 20 | F25: =COUNTA(F5:F24) -> 20 | G25: 所有可能数 | H25: =PRODUCT(B25:F25) -> 3200000
A27: 【图案次数统计】
A28: 图案 | B28: 轮1 | C28: 轮2 | D28: 轮3 | E28: 轮4 | F28: 轮5
A29: any | B29: =B$25 -> 20 | C29: =C$25 -> 20 | D29: =D$25 -> 20 | E29: =E$25 -> 20 | F29: =F$25 -> 20
A30: W | B30: =COUNTIF(B$5:B$24,$A30) -> 0 | C30: =COUNTIF(C$5:C$24,$A30) -> 1 | D30: =COUNTIF(D$5:D$24,$A30) -> 1 | E30: =COUNTIF(E$5:E$24,$A30) -> 1 | F30: =COUNTIF(F$5:F$24,$A30) -> 1
A31: K | B31: =COUNTIF(B$5:B$24,$A31) -> 1 | C31: =COUNTIF(C$5:C$24,$A31) -> 3 | D31: =COUNTIF(D$5:D$24,$A31) -> 3 | E31: =COUNTIF(E$5:E$24,$A31) -> 3 | F31: =COUNTIF(F$5:F$24,$A31) -> 3
A32: Q | B32: =COUNTIF(B$5:B$24,$A32) -> 3 | C32: =COUNTIF(C$5:C$24,$A32) -> 3 | D32: =COUNTIF(D$5:D$24,$A32) -> 3 | E32: =COUNTIF(E$5:E$24,$A32) -> 3 | F32: =COUNTIF(F$5:F$24,$A32) -> 3
A33: J | B33: =COUNTIF(B$5:B$24,$A33) -> 4 | C33: =COUNTIF(C$5:C$24,$A33) -> 5 | D33: =COUNTIF(D$5:D$24,$A33) -> 4 | E33: =COUNTIF(E$5:E$24,$A33) -> 4 | F33: =COUNTIF(F$5:F$24,$A33) -> 4
A34: 10 | B34: =COUNTIF(B$5:B$24,$A34) -> 5 | C34: =COUNTIF(C$5:C$24,$A34) -> 3 | D34: =COUNTIF(D$5:D$24,$A34) -> 4 | E34: =COUNTIF(E$5:E$24,$A34) -> 4 | F34: =COUNTIF(F$5:F$24,$A34) -> 4
A35: 9 | B35: =COUNTIF(B$5:B$24,$A35) -> 6 | C35: =COUNTIF(C$5:C$24,$A35) -> 4 | D35: =COUNTIF(D$5:D$24,$A35) -> 4 | E35: =COUNTIF(E$5:E$24,$A35) -> 4 | F35: =COUNTIF(F$5:F$24,$A35) -> 4
A36: S | B36: =COUNTIF(B$5:B$24,$A36) -> 1 | C36: =COUNTIF(C$5:C$24,$A36) -> 1 | D36: =COUNTIF(D$5:D$24,$A36) -> 1 | E36: =COUNTIF(E$5:E$24,$A36) -> 1 | F36: =COUNTIF(F$5:F$24,$A36) -> 1
A37: 3S（3 行视窗 × Scatter 个数） | B37: =3*B36 -> 3 | C37: =3*C36 -> 3 | D37: =3*D36 -> 3 | E37: =3*E36 -> 3 | F37: =3*F36 -> 3
A39: 【赔付表】列 = 连线数
A40: 图案 | B40: 3 | C40: 4 | D40: 5
A41: K | B41: 5 | C41: 30 | D41: 100
A42: Q | B42: 5 | C42: 25 | D42: 100
A43: J | B43: 5 | C43: 20 | D43: 75
...

Sheet RTP分解
A1: 主游戏 RTP 的 WILD 三分法：普通符号 RTP + WILD 介入 RTP + WILD 图案 RTP
A3: 【口径 A：不含 WILD】把 WILD 从转轮里剔除，仅按符号自身计数
A4: 符号 | B4: m1 | C4: m2 | D4: m3 | E4: m4 | F4: m5 | G4: X4 | H4: X5 | I4: N5 | J4: 5连次数 | K4: 4连次数 | L4: 3连次数 | M4: 赔5 | N4: 赔4 | O4: 赔3 | P4: RTP贡献 | Q4: 备注
A5: K | B5: =滚轴与赔付!B$31 -> 1 | C5: =滚轴与赔付!C$31 -> 3 | D5: =滚轴与赔付!D$31 -> 3 | E5: =滚轴与赔付!E$31 -> 3 | F5: =滚轴与赔付!F$31 -> 3 | G5: =滚轴与赔付!$E$25-E5 -> 17 | H5: =滚轴与赔付!$F$25-F5 -> 17 | I5: =滚轴与赔付!$F$25 -> 20 | J5: =B5*C5*D5*E5*F5 -> 81 | K5: =B5*C5*D5*E5*H5 -> 459 | L5: =B5*C5*D5*G5*I5 -> 3060 | M5: =VLOOKUP($A5,滚轴与赔付!$A$41:$D$45,4,FALSE()) -> 100 | N5: =VLOOKUP($A5,滚轴与赔付!$A$41:$D$45,3,FALSE()) -> 30 | O5: =VLOOKUP($A5,滚轴与赔付!$A$41:$D$45,2,FALSE()) -> 5 | P5: =(J5*M5+K5*N5+L5*O5)/滚轴与赔付!$H$25 -> 0.011615625
A6: Q | B6: =滚轴与赔付!B$32 -> 3 | C6: =滚轴与赔付!C$32 -> 3 | D6: =滚轴与赔付!D$32 -> 3 | E6: =滚轴与赔付!E$32 -> 3 | F6: =滚轴与赔付!F$32 -> 3 | G6: =滚轴与赔付!$E$25-E6 -> 17 | H6: =滚轴与赔付!$F$25-F6 -> 17 | I6: =滚轴与赔付!$F$25 -> 20 | J6: =B6*C6*D6*E6*F6 -> 243 | K6: =B6*C6*D6*E6*H6 -> 1377 | L6: =B6*C6*D6*G6*I6 -> 9180 | M6: =VLOOKUP($A6,滚轴与赔付!$A$41:$D$45,4,FALSE()) -> 100 | N6: =VLOOKUP($A6,滚轴与赔付!$A$41:$D$45,3,FALSE()) -> 25 | O6: =VLOOKUP($A6,滚轴与赔付!$A$41:$D$45,2,FALSE()) -> 5 | P6: =(J6*M6+K6*N6+L6*O6)/滚轴与赔付!$H$25 -> 0.032695312
A7: J | B7: =滚轴与赔付!B$33 -> 4 | C7: =滚轴与赔付!C$33 -> 5 | D7: =滚轴与赔付!D$33 -> 4 | E7: =滚轴与赔付!E$33 -> 4 | F7: =滚轴与赔付!F$33 -> 4 | G7: =滚轴与赔付!$E$25-E7 -> 16 | H7: =滚轴与赔付!$F$25-F7 -> 16 | I7: =滚轴与赔付!$F$25 -> 20 | J7: =B7*C7*D7*E7*F7 -> 1280 | K7: =B7*C7*D7*E7*H7 -> 5120 | L7: =B7*C7*D7*G7*I7 -> 25600 | M7: =VLOOKUP($A7,滚轴与赔付!$A$41:$D$45,4,FALSE()) -> 75 | N7: =VLOOKUP($A7,滚轴与赔付!$A$41:$D$45,3,FALSE()) -> 20 | O7: =VLOOKUP($A7,滚轴与赔付!$A$41:$D$45,2,FALSE()) -> 5 | P7: =(J7*M7+K7*N7+L7*O7)/滚轴与赔付!$H$25 -> 0.102
A8: 10 | B8: =滚轴与赔付!B$34 -> 5 | C8: =滚轴与赔付!C$34 -> 3 | D8: =滚轴与赔付!D$34 -> 4 | E8: =滚轴与赔付!E$34 -> 4 | F8: =滚轴与赔付!F$34 -> 4 | G8: =滚轴与赔付!$E$25-E8 -> 16 | H8: =滚轴与赔付!$F$25-F8 -> 16 | I8: =滚轴与赔付!$F$25 -> 20 | J8: =B8*C8*D8*E8*F8 -> 960 | K8: =B8*C8*D8*E8*H8 -> 3840 | L8: =B8*C8*D8*G8*I8 -> 19200 | M8: =VLOOKUP($A8,滚轴与赔付!$A$41:$D$45,4,FALSE()) -> 75 | N8: =VLOOKUP($A8,滚轴与赔付!$A$41:$D$45,3,FALSE()) -> 20 | O8: =VLOOKUP($A8,滚轴与赔付!$A$41:$D$45,2,FALSE()) -> 5 | P8: =(J8*M8+K8*N8+L8*O8)/滚轴与赔付!$H$25 -> 0.0765
A9: 9 | B9: =滚轴与赔付!B$35 -> 6 | C9: =滚轴与赔付!C$35 -> 4 | D9: =滚轴与赔付!D$35 -> 4 | E9: =滚轴与赔付!E$35 -> 4 | F9: =滚轴与赔付!F$35 -> 4 | G9: =滚轴与赔付!$E$25-E9 -> 16 | H9: =滚轴与赔付!$F$25-F9 -> 16 | I9: =滚轴与赔付!$F$25 -> 20 | J9: =B9*C9*D9*E9*F9 -> 1536 | K9: =B9*C9*D9*E9*H9 -> 6144 | L9: =B9*C9*D9*G9*I9 -> 30720 | M9: =VLOOKUP($A9,滚轴与赔付!$A$41:$D$45,4,FALSE()) -> 50 | N9: =VLOOKUP($A9,滚轴与赔付!$A$41:$D$45,3,FALSE()) -> 10 | O9: =VLOOKUP($A9,滚轴与赔付!$A$41:$D$45,2,FALSE()) -> 5 | P9: =(J9*M9+K9*N9+L9*O9)/滚轴与赔付!$H$25 -> 0.0912
A10: 合计 | J10: =SUM(J5:J9) -> 4100 | K10: =SUM(K5:K9) -> 16940 | L10: =SUM(L5:L9) -> 87760 | M10: → RTP | P10: =SUM(P5:P9) -> 0.31401094 | Q10: → 普通符号 RTP
A12: 【口径 B：含 WILD】mᵢ = 该列符号数 + 该列 WILD 数（WILD 可替代该符号）
A13: 符号 | B13: m1 | C13: m2 | D13: m3 | E13: m4 | F13: m5 | G13: X4 | H13: X5 | I13: N5 | J13: 5连次数 | K13: 4连次数 | L13: 3连次数 | M13: 赔5 | N13: 赔4 | O13: 赔3 | P13: RTP贡献 | Q13: 备注
A14: K | B14: =滚轴与赔付!B$31+滚轴与赔付!B$30 -> 1 | C14: =滚轴与赔付!C$31+滚轴与赔付!C$30 -> 4 | D14: =滚轴与赔付!D$31+滚轴与赔付!D$30 -> 4 | E14: =滚轴与赔付!E$31+滚轴与赔付!E$30 -> 4 | F14: =滚轴与赔付!F$31+滚轴与赔付!F$30 -> 4 | G14: =滚轴与赔付!$E$25-E14 -> 16 | H14: =滚轴与赔付!$F$25-F14 -> 16 | I14: =滚轴与赔付!$F$25 -> 20 | J14: =B14*C14*D14*E14*F14 -> 256 | K14: =B14*C14*D14*E14*H14 -> 1024 | L14: =B14*C14*D14*G14*I14 -> 5120 | M14: =VLOOKUP($A14,滚轴与赔付!$A$41:$D$45,4,FALSE()) -> 100 | N14: =VLOOKUP($A14,滚轴与赔付!$A$41:$D$45,3,FALSE()) -> 30 | O14: =VLOOKUP($A14,滚轴与赔付!$A$41:$D$45,2,FALSE()) -> 5 | P14: =(J14*M14+K14*N14+L14*O14)/滚轴与赔付!$H$25 -> 0.0256
A15: Q | B15: =滚轴与赔付!B$32+滚轴与赔付!B$30 -> 3 | C15: =滚轴与赔付!C$32+滚轴与赔付!C$30 -> 4 | D15: =滚轴与赔付!D$32+滚轴与赔付!D$30 -> 4 | E15: =滚轴与赔付!E$32+滚轴与赔付!E$30 -> 4 | F15: =滚轴与赔付!F$32+滚轴与赔付!F$30 -> 4 | G15: =滚轴与赔付!$E$25-E15 -> 16 | H15: =滚轴与赔付!$F$25-F15 -> 16 | I15: =滚轴与赔付!$F$25 -> 20 | J15: =B15*C15*D15*E15*F15 -> 768 | K15: =B15*C15*D15*E15*H15 -> 3072 | L15: =B15*C15*D15*G15*I15 -> 15360 | M15: =VLOOKUP($A15,滚轴与赔付!$A$41:$D$45,4,FALSE()) -> 100 | N15: =VLOOKUP($A15,滚轴与赔付!$A$41:$D$45,3,FALSE()) -> 25 | O15: =VLOOKUP($A15,滚轴与赔付!$A$41:$D$45,2,FALSE()) -> 5 | P15: =(J15*M15+K15*N15+L15*O15)/滚轴与赔付!$H$25 -> 0.072
A16: J | B16: =滚轴与赔付!B$33+滚轴与赔付!B$30 -> 4 | C16: =滚轴与赔付!C$33+滚轴与赔付!C$30 -> 6 | D16: =滚轴与赔付!D$33+滚轴与赔付!D$30 -> 5 | E16: =滚轴与赔付!E$33+滚轴与赔付!E$30 -> 5 | F16: =滚轴与赔付!F$33+滚轴与赔付!F$30 -> 5 | G16: =滚轴与赔付!$E$25-E16 -> 15 | H16: =滚轴与赔付!$F$25-F16 -> 15 | I16: =滚轴与赔付!$F$25 -> 20 | J16: =B16*C16*D16*E16*F16 -> 3000 | K16: =B16*C16*D16*E16*H16 -> 9000 | L16: =B16*C16*D16*G16*I16 -> 36000 | M16: =VLOOKUP($A16,滚轴与赔付!$A$41:$D$45,4,FALSE()) -> 75 | N16: =VLOOKUP($A16,滚轴与赔付!$A$41:$D$45,3,FALSE()) -> 20 | O16: =VLOOKUP($A16,滚轴与赔付!$A$41:$D$45,2,FALSE()) -> 5 | P16: =(J16*M16+K16*N16+L16*O16)/滚轴与赔付!$H$25 -> 0.1828125
A17: 10 | B17: =滚轴与赔付!B$34+滚轴与赔付!B$30 -> 5 | C17: =滚轴与赔付!C$34+滚轴与赔付!C$30 -> 4 | D17: =滚轴与赔付!D$34+滚轴与赔付!D$30 -> 5 | E17: =滚轴与赔付!E$34+滚轴与赔付!E$30 -> 5 | F17: =滚轴与赔付!F$34+滚轴与赔付!F$30 -> 5 | G17: =滚轴与赔付!$E$25-E17 -> 15 | H17: =滚轴与赔付!$F$25-F17 -> 15 | I17: =滚轴与赔付!$F$25 -> 20 | J17: =B17*C17*D17*E17*F17 -> 2500 | K17: =B17*C17*D17*E17*H17 -> 7500 | L17: =B17*C17*D17*G17*I17 -> 30000 | M17: =VLOOKUP($A17,滚轴与赔付!$A$41:$D$45,4,FALSE()) -> 75 | N17: =VLOOKUP($A17,滚轴与赔付!$A$41:$D$45,3,FALSE()) -> 20 | O17: =VLOOKUP($A17,滚轴与赔付!$A$41:$D$45,2,FALSE()) -> 5 | P17: =(J17*M17+K17*N17+L17*O17)/滚轴与赔付!$H$25 -> 0.15234375
A18: 9 | B18: =滚轴与赔付!B$35+滚轴与赔付!B$30 -> 6 | C18: =滚轴与赔付!C$35+滚轴与赔付!C$30 -> 5 | D18: =滚轴与赔付!D$35+滚轴与赔付!D$30 -> 5 | E18: =滚轴与赔付!E$35+滚轴与赔付!E$30 -> 5 | F18: =滚轴与赔付!F$35+滚轴与赔付!F$30 -> 5 | G18: =滚轴与赔付!$E$25-E18 -> 15 | H18: =滚轴与赔付!$F$25-F18 -> 15 | I18: =滚轴与赔付!$F$25 -> 20 | J18: =B18*C18*D18*E18*F18 -> 3750 | K18: =B18*C18*D18*E18*H18 -> 11250 | L18: =B18*C18*D18*G18*I18 -> 45000 | M18: =VLOOKUP($A18,滚轴与赔付!$A$41:$D$45,4,FALSE()) -> 50 | N18: =VLOOKUP($A18,滚轴与赔付!$A$41:$D$45,3,FALSE()) -> 10 | O18: =VLOOKUP($A18,滚轴与赔付!$A$41:$D$45,2,FALSE()) -> 5 | P18: =(J18*M18+K18*N18+L18*O18)/滚轴与赔付!$H$25 -> 0.1640625
A19: 合计 | J19: =SUM(J14:J18) -> 10274 | K19: =SUM(K14:K18) -> 31846 | L19: =SUM(L14:L18) -> 131480 | M19: → RTP | P19: =SUM(P14:P18) -> 0.59681875 | Q19: → 普通符号 + WILD 介入 RTP
A21: 【口径 C：WILD 自己作为图案】按 WILD 的赔付表计算 WWW / WWWW / WWWWW
A22: 符号 | B22: m1 | C22: m2 | D22: m3 | E22: m4 | F22: m5 | G22: X4 | H22: X5 | I22: N5 | J22: 5连次数 | K22: 4连次数 | L22: 3连次数 | M22: 赔5 | N22: 赔4 | O22: 赔3 | P22: RTP贡献 | Q22: 备注
A23: W | B23: =滚轴与赔付!B$30 -> 0 | C23: =滚轴与赔付!C$30 -> 1 | D23: =滚轴与赔付!D$30 -> 1 | E23: =滚轴与赔付!E$30 -> 1 | F23: =滚轴与赔付!F$30 -> 1 | G23: =滚轴与赔付!$E$25-E23 -> 19 | H23: =滚轴与赔付!$F$25-F23 -> 19 | I23: =滚轴与赔付!$F$25 -> 20 | J23: =B23*C23*D23*E23*F23 -> 0 | K23: =B23*C23*D23*E23*H23 -> 0 | L23: =B23*C23*D23*G23*I23 -> 0 | M23: =VLOOKUP($A23,滚轴与赔付!$A$41:$D$46,4,FALSE()) -> 100 | N23: =VLOOKUP($A23,滚轴与赔付!$A$41:$D$46,3,FALSE()) -> 30 | O23: =VLOOKUP($A23,滚轴与赔付!$A$41:$D$46,2,FALSE()) -> 5 | P23: =(J23*M23+K23*N23+L23*O23)/滚轴与赔付!$H$25 -> 0
A24: 合计 | J24: =SUM(J23) -> 0 | K24: =SUM(K23) -> 0 | L24: =SUM(L23) -> 0 | M24: → RTP | P24: =SUM(P23) -> 0 | Q24: → WILD 图案 RTP
A26: 【汇总】
A27: 普通符号 RTP | D27: =P10 -> 0.31401094
A28: WILD 介入 RTP = 口径 B − 口径 A | D28: =P19-P10 -> 0.28280781
A29: WILD 图案 RTP | D29: =P24 -> 0
A30: 主游戏连线 RTP = 三者之和 | D30: =D27+D28+D29 -> 0.59681875
A31: 主游戏 Scatter 赔付 RTP | D31: =滚轴与赔付!$B$47*(10*0.15^3*0.85^2+5*0.15^4*0.85+0.15^5) -> 0.05322375
A32: 主游戏总 RTP（连线 + Scatter） | D32: =D30+D31 -> 0.6500425 | E32: ← 与《Part II》主游戏 65.00% 一致
A34: 【原文示例对照】
A35: 普通符号 RTP（原文示例） | D35: 0.3
A36: WILD 介入 RTP（原文示例） | D36: 1.11
A37: WILD 图案 RTP（原文示例） | D37: 0.0097
A38: 原文示例主游戏 RTP 合计 | D38: =D35+D36+D37 -> 1.4197
A39: 原文自述「随便定的图案所以 RTP 有点（高）」，141.97% 属教学示例，不是商业目标值。
A40: 结构一致、数值不同：三个分项的含义与算法相同，只是转轮与赔付表不同。

Sheet 首列WILD
A1: 首列 WILD：第 1 轴 WILD 覆盖率 w → 主游戏连线 RTP
A3: 【规则与模型】
A4: 规则：第 1 轴为万能起手轴（第 1 列出现 WILD；极端情形整列都是 WILD）
A5: 源码提示：原文指出「首列 WILD 实际不属于特殊 WILD 图案」
A6: 量化：w = 第 1 列里 WILD 的格数（0~20），其余符号按 (20−w)/20 等比压缩
A7: m₁(w) = 第 1 列原符号数 × (1 − w/20) + w
A9: 【逐符号「尾因子」T_S（与 w 无关的常数）】
A10: 符号 | B10: 轮1 原符号数 | C10: m2 | D10: m3 | E10: m4 | F10: m5 | G10: X4 | H10: X5 | I10: N5 | J10: 赔5 | K10: 赔4 | L10: 赔3 | M10: m2·m3 | N10: m2·m3·m4 | O10: T_S
A11: K | B11: =滚轴与赔付!B$31 -> 1 | C11: =滚轴与赔付!C$31+滚轴与赔付!C$30 -> 4 | D11: =滚轴与赔付!D$31+滚轴与赔付!D$30 -> 4 | E11: =滚轴与赔付!E$31+滚轴与赔付!E$30 -> 4 | F11: =滚轴与赔付!F$31+滚轴与赔付!F$30 -> 4 | G11: =滚轴与赔付!$E$25-E11 -> 16 | H11: =滚轴与赔付!$F$25-F11 -> 16 | I11: =滚轴与赔付!$F$25 -> 20 | J11: =VLOOKUP($A11,滚轴与赔付!$A$41:$D$45,4,FALSE()) -> 100 | K11: =VLOOKUP($A11,滚轴与赔付!$A$41:$D$45,3,FALSE()) -> 30 | L11: =VLOOKUP($A11,滚轴与赔付!$A$41:$D$45,2,FALSE()) -> 5 | M11: =C11*D11 -> 16 | N11: =C11*D11*E11 -> 64 | O11: =C11*D11*E11*F11*J11+N11*H11*K11+M11*G11*I11*L11 -> 81920
A12: Q | B12: =滚轴与赔付!B$32 -> 3 | C12: =滚轴与赔付!C$32+滚轴与赔付!C$30 -> 4 | D12: =滚轴与赔付!D$32+滚轴与赔付!D$30 -> 4 | E12: =滚轴与赔付!E$32+滚轴与赔付!E$30 -> 4 | F12: =滚轴与赔付!F$32+滚轴与赔付!F$30 -> 4 | G12: =滚轴与赔付!$E$25-E12 -> 16 | H12: =滚轴与赔付!$F$25-F12 -> 16 | I12: =滚轴与赔付!$F$25 -> 20 | J12: =VLOOKUP($A12,滚轴与赔付!$A$41:$D$45,4,FALSE()) -> 100 | K12: =VLOOKUP($A12,滚轴与赔付!$A$41:$D$45,3,FALSE()) -> 25 | L12: =VLOOKUP($A12,滚轴与赔付!$A$41:$D$45,2,FALSE()) -> 5 | M12: =C12*D12 -> 16 | N12: =C12*D12*E12 -> 64 | O12: =C12*D12*E12*F12*J12+N12*H12*K12+M12*G12*I12*L12 -> 76800
A13: J | B13: =滚轴与赔付!B$33 -> 4 | C13: =滚轴与赔付!C$33+滚轴与赔付!C$30 -> 6 | D13: =滚轴与赔付!D$33+滚轴与赔付!D$30 -> 5 | E13: =滚轴与赔付!E$33+滚轴与赔付!E$30 -> 5 | F13: =滚轴与赔付!F$33+滚轴与赔付!F$30 -> 5 | G13: =滚轴与赔付!$E$25-E13 -> 15 | H13: =滚轴与赔付!$F$25-F13 -> 15 | I13: =滚轴与赔付!$F$25 -> 20 | J13: =VLOOKUP($A13,滚轴与赔付!$A$41:$D$45,4,FALSE()) -> 75 | K13: =VLOOKUP($A13,滚轴与赔付!$A$41:$D$45,3,FALSE()) -> 20 | L13: =VLOOKUP($A13,滚轴与赔付!$A$41:$D$45,2,FALSE()) -> 5 | M13: =C13*D13 -> 30 | N13: =C13*D13*E13 -> 150 | O13: =C13*D13*E13*F13*J13+N13*H13*K13+M13*G13*I13*L13 -> 146250
A14: 10 | B14: =滚轴与赔付!B$34 -> 5 | C14: =滚轴与赔付!C$34+滚轴与赔付!C$30 -> 4 | D14: =滚轴与赔付!D$34+滚轴与赔付!D$30 -> 5 | E14: =滚轴与赔付!E$34+滚轴与赔付!E$30 -> 5 | F14: =滚轴与赔付!F$34+滚轴与赔付!F$30 -> 5 | G14: =滚轴与赔付!$E$25-E14 -> 15 | H14: =滚轴与赔付!$F$25-F14 -> 15 | I14: =滚轴与赔付!$F$25 -> 20 | J14: =VLOOKUP($A14,滚轴与赔付!$A$41:$D$45,4,FALSE()) -> 75 | K14: =VLOOKUP($A14,滚轴与赔付!$A$41:$D$45,3,FALSE()) -> 20 | L14: =VLOOKUP($A14,滚轴与赔付!$A$41:$D$45,2,FALSE()) -> 5 | M14: =C14*D14 -> 20 | N14: =C14*D14*E14 -> 100 | O14: =C14*D14*E14*F14*J14+N14*H14*K14+M14*G14*I14*L14 -> 97500
A15: 9 | B15: =滚轴与赔付!B$35 -> 6 | C15: =滚轴与赔付!C$35+滚轴与赔付!C$30 -> 5 | D15: =滚轴与赔付!D$35+滚轴与赔付!D$30 -> 5 | E15: =滚轴与赔付!E$35+滚轴与赔付!E$30 -> 5 | F15: =滚轴与赔付!F$35+滚轴与赔付!F$30 -> 5 | G15: =滚轴与赔付!$E$25-E15 -> 15 | H15: =滚轴与赔付!$F$25-F15 -> 15 | I15: =滚轴与赔付!$F$25 -> 20 | J15: =VLOOKUP($A15,滚轴与赔付!$A$41:$D$45,4,FALSE()) -> 50 | K15: =VLOOKUP($A15,滚轴与赔付!$A$41:$D$45,3,FALSE()) -> 10 | L15: =VLOOKUP($A15,滚轴与赔付!$A$41:$D$45,2,FALSE()) -> 5 | M15: =C15*D15 -> 25 | N15: =C15*D15*E15 -> 125 | O15: =C15*D15*E15*F15*J15+N15*H15*K15+M15*G15*I15*L15 -> 87500
A16: T_S = Πm₂..m₅ × 赔5 + (m₂·m₃·m₄) × X₅ × 赔4 + (m₂·m₃) × X₄ × N₅ × 赔3
A17: 于是 主游戏连线 RTP(w) = Σ_S [ m₁_S(w) × T_S ] ÷ 所有可能数，其中 m₁_S(w) = B_S × (1 − w/20) + w。
A19: 【敏感性：w → 主游戏连线 RTP】
A20: w（轮1 WILD 格数） | B20: Σ m₁·T_S | C20: 主游戏连线 RTP | D20: 相对 w=0 的倍数 | E20: 说明
A21: 0 | B21: =SUMPRODUCT(($B$11:$B$15*(1-$A21/20)+$A21)*$O$11:$O$15) -> 1909820 | C21: =B21/滚轴与赔付!$H$25 -> 0.59681875 | D21: =C21/$C$21 -> 1 | E21: 基准：首列无 WILD（= 口径 B 的连线 RTP）
A22: 1 | B22: =SUMPRODUCT(($B$11:$B$15*(1-$A22/20)+$A22)*$O$11:$O$15) -> 2304299 | C22: =B22/滚轴与赔付!$H$25 -> 0.72009344 | D22: =C22/$C$21 -> 1.206553
A23: 2 | B23: =SUMPRODUCT(($B$11:$B$15*(1-$A23/20)+$A23)*$O$11:$O$15) -> 2698778 | C23: =B23/滚轴与赔付!$H$25 -> 0.84336813 | D23: =C23/$C$21 -> 1.4131059
A24: 3 | B24: =SUMPRODUCT(($B$11:$B$15*(1-$A24/20)+$A24)*$O$11:$O$15) -> 3093257 | C24: =B24/滚轴与赔付!$H$25 -> 0.96664281 | D24: =C24/$C$21 -> 1.6196589
A25: 4 | B25: =SUMPRODUCT(($B$11:$B$15*(1-$A25/20)+$A25)*$O$11:$O$15) -> 3487736 | C25: =B25/滚轴与赔付!$H$25 -> 1.0899175 | D25: =C25/$C$21 -> 1.8262119
A26: 5 | B26: =SUMPRODUCT(($B$11:$B$15*(1-$A26/20)+$A26)*$O$11:$O$15) -> 3882215 | C26: =B26/滚轴与赔付!$H$25 -> 1.2131922 | D26: =C26/$C$21 -> 2.0327649
A27: 6 | B27: =SUMPRODUCT(($B$11:$B$15*(1-$A27/20)+$A27)*$O$11:$O$15) -> 4276694 | C27: =B27/滚轴与赔付!$H$25 -> 1.3364669 | D27: =C27/$C$21 -> 2.2393178
A28: 7 | B28: =SUMPRODUCT(($B$11:$B$15*(1-$A28/20)+$A28)*$O$11:$O$15) -> 4671173 | C28: =B28/滚轴与赔付!$H$25 -> 1.4597416 | D28: =C28/$C$21 -> 2.4458708
A29: 8 | B29: =SUMPRODUCT(($B$11:$B$15*(1-$A29/20)+$A29)*$O$11:$O$15) -> 5065652 | C29: =B29/滚轴与赔付!$H$25 -> 1.5830163 | D29: =C29/$C$21 -> 2.6524238
A30: 9 | B30: =SUMPRODUCT(($B$11:$B$15*(1-$A30/20)+$A30)*$O$11:$O$15) -> 5460131 | C30: =B30/滚轴与赔付!$H$25 -> 1.7062909 | D30: =C30/$C$21 -> 2.8589768
A31: 10 | B31: =SUMPRODUCT(($B$11:$B$15*(1-$A31/20)+$A31)*$O$11:$O$15) -> 5854610 | C31: =B31/滚轴与赔付!$H$25 -> 1.8295656 | D31: =C31/$C$21 -> 3.0655297
A32: 11 | B32: =SUMPRODUCT(($B$11:$B$15*(1-$A32/20)+$A32)*$O$11:$O$15) -> 6249089 | C32: =B32/滚轴与赔付!$H$25 -> 1.9528403 | D32: =C32/$C$21 -> 3.2720827
A33: 12 | B33: =SUMPRODUCT(($B$11:$B$15*(1-$A33/20)+$A33)*$O$11:$O$15) -> 6643568 | C33: =B33/滚轴与赔付!$H$25 -> 2.076115 | D33: =C33/$C$21 -> 3.4786357
... A40: 19 | B40: =SUMPRODUCT(($B$11:$B$15*(1-$A40/20)+$A40)*$O$11:$O$15) -> 9404921 | C40: =B40/滚轴与赔付!$H$25 -> 2.9390378 | D40: =C40/$C$21 -> 4.9245065
A41: 20 | B41: =SUMPRODUCT(($B$11:$B$15*(1-$A41/20)+$A41)*$O$11:$O$15) -> 9799400 | C41: =B41/滚轴与赔付!$H$25 -> 3.0623125 | D41: =C41/$C$21 -> 5.1310595 | E41: 极端：第 1 列整列 WILD
A43: 【两个关键场景】
A44: w = 0（首列无 WILD）主游戏连线 RTP | C44: =C21 -> 0.59681875
A45: w = 20（首列整列 WILD）主游戏连线 RTP | C45: =C41 -> 3.0623125
A46: 膨胀倍数 | C46: =C45/C44 -> 5.1310595
A48: 工程含义：首列 WILD 会让「所有符号的 3 连」几乎必中，RTP 迅速越过 100%。
A49: 因此这类规则必须配合：① 首列 WILD 的覆盖率上限；② 该轴专属的低赔付表；③ 3 连的高门槛过滤（如仅 4 连起赔）。
A51: 原文对照：原文示例的主游戏 RTP = 30% + 111% + 0.97% ≈ 141.97%，同样出在教学示例区间。

Sheet 四类WILD
A1: 四类 WILD 的 RTP 计算方法（一种特殊出现规则 + 三种特殊玩法）
A3: 【四类 WILD 概览（原文）】
A4: # | B4: 类型 | C4: 出现 / 触发规则 | D4: RTP 计算要点 | E4: 常见轴位
A5: 1 | B5: 首列 WILD（规则变化） | C5: 第 1 轴为万能起手，修复起始断线 | D5: 抬高第 1 轴的 m₁（覆盖率 w）→ 见「首列WILD」页 | E5: 轴 1
A6: 2 | B6: 倍率 WILD | C6: 含 WILD 的连线按倍率相乘（×2 / ×3 … 或区间倍率） | D6: 该连线赔付 × E[倍率]，见下方「一、倍率 WILD」 | E6: 任意轴
A7: 3 | B7: 扩展 WILD | C7: 命中即整列变 WILD | D7: 命中后该列 mᵢ = Nᵢ（整列变 W），按发生概率与基准做混合，见下方「二」 | E7: 常在轴 2 / 3 / 4
A8: 4 | B8: 黏性 WILD | C8: Free Game 内命中后停留多局，逐局累积提升连线概率 | D8: 状态机：局序 n 的期望黏住数 k_n → 覆盖率 w → 该局 RTP，见下方「三」 | E8: 任意轴
A10: 原文提示：首列 WILD 实际不属于「特殊 WILD 图案」—— 它改变的是一条规则，而不是一种符号形态。
A11: 四种 WILD 的共同计算前提：WILD 可替代任何图案（除 Scatter），所以 WILD 连线只会被 Scatter 或其他不可替换图案中断。
A13: 【一、倍率 WILD：含 WILD 的连线按倍率相乘】
A14: 倍率档 | B14: 倍率 | C14: 权重 | D14: 加权贡献 | E14: 说明
A15: ×2 | B15: 2 | C15: 6 | D15: =B15*C15 -> 12 | E15: 最常见档位
A16: ×3 | B16: 3 | C16: 3 | D16: =B16*C16 -> 9
A17: ×5 | B17: 5 | C17: 1 | D17: =B17*C17 -> 5 | E17: 区间倍率可拆成多档
A18: 合计 | C18: =SUM(C15:C17) -> 10 | D18: =SUM(D15:D17) -> 26
A20: E[倍率] = Σ(倍率 × 权重) ÷ Σ权重 | B20: =D18/C18 -> 2.6
A22: WILD 介入 RTP（基准，不含倍率） | C22: =RTP分解!$D$28 -> 0.28280781
A23: 倍率后 WILD 介入 RTP = 基准 × E[倍率] | C23: =C22*$B$20 -> 0.73530031
A24: 主游戏连线 RTP（含倍率 WILD） | C24: =RTP分解!$D$27+C23+RTP分解!$D$29 -> 1.0493112
A25: 相对基准的膨胀倍数 | C25: =C24/RTP分解!$D$30 -> 1.7581741
A27: 要点：倍率只乘在「含 WILD 的那条连线」上，因此在 RTP 上表现为对「WILD 介入 RTP」这一分项的放大，而不会放大普通符号 RTP。
A29: 【二、扩展 WILD：命中即整列变 WILD】
A30: 扩展轴（2~5） | B30: 3
A31: 该轴出现 WILD 的概率 q（≈ 3 × 该轴 W 数 ÷ 该轴格数） | B31: 0.15
A32: 符号 | B32: m1′ | C32: m2′ | D32: m3′ | E32: m4′ | F32: m5′ | G32: X4′ | H32: X5′ | I32: N5 | J32: 5连 | K32: 4连 | L32: 3连 | M32: 赔5 | N32: 赔4 | O32: 赔3 | P32: 扩展前 RTP | Q32: 扩展后 RTP | R32: 混合 RTP
A33: K | B33: =IF($B$30=1,滚轴与赔付!$B$25,RTP分解!B14) -> 1 | C33: =IF($B$30=2,滚轴与赔付!$C$25,RTP分解!C14) -> 4 | D33: =IF($B$30=3,滚轴与赔付!$D$25,RTP分解!D14) -> 20 | E33: =IF($B$30=4,滚轴与赔付!$E$25,RTP分解!E14) -> 4 | F33: =IF($B$30=5,滚轴与赔付!$F$25,RTP分解!F14) -> 4 | G33: =滚轴与赔付!$E$25-E33 -> 16 | H33: =滚轴与赔付!$F$25-F33 -> 16 | I33: =滚轴与赔付!$F$25 -> 20 | J33: =B33*C33*D33*E33*F33 -> 1280 | K33: =B33*C33*D33*E33*H33 -> 5120 | L33: =B33*C33*D33*G33*I33 -> 25600 | M33: =VLOOKUP($A33,滚轴与赔付!$A$41:$D$45,4,FALSE()) -> 100 | N33: =VLOOKUP($A33,滚轴与赔付!$A$41:$D$45,3,FALSE()) -> 30 | O33: =VLOOKUP($A33,滚轴与赔付!$A$41:$D$45,2,FALSE()) -> 5 | P33: =RTP分解!$P$14 -> 0.0256 | Q33: =(J33*M33+K33*N33+L33*O33)/滚轴与赔付!$H$25 -> 0.128 | R33: =(1-$B$31)*P33+$B$31*Q33 -> 0.04096
A34: Q | B34: =IF($B$30=1,滚轴与赔付!$B$25,RTP分解!B15) -> 3 | C34: =IF($B$30=2,滚轴与赔付!$C$25,RTP分解!C15) -> 4 | D34: =IF($B$30=3,滚轴与赔付!$D$25,RTP分解!D15) -> 20 | E34: =IF($B$30=4,滚轴与赔付!$E$25,RTP分解!E15) -> 4 | F34: =IF($B$30=5,滚轴与赔付!$F$25,RTP分解!F15) -> 4 | G34: =滚轴与赔付!$E$25-E34 -> 16 | H34: =滚轴与赔付!$F$25-F34 -> 16 | I34: =滚轴与赔付!$F$25 -> 20 | J34: =B34*C34*D34*E34*F34 -> 3840 | K34: =B34*C34*D34*E34*H34 -> 15360 | L34: =B34*C34*D34*G34*I34 -> 76800 | M34: =VLOOKUP($A34,滚轴与赔付!$A$41:$D$45,4,FALSE()) -> 100 | N34: =VLOOKUP($A34,滚轴与赔付!$A$41:$D$45,3,FALSE()) -> 25 | O34: =VLOOKUP($A34,滚轴与赔付!$A$41:$D$45,2,FALSE()) -> 5 | P34: =RTP分解!$P$15 -> 0.072 | Q34: =(J34*M34+K34*N34+L34*O34)/滚轴与赔付!$H$25 -> 0.36 | R34: =(1-$B$31)*P34+$B$31*Q34 -> 0.1152
A35: J | B35: =IF($B$30=1,滚轴与赔付!$B$25,RTP分解!B16) -> 4 | C35: =IF($B$30=2,滚轴与赔付!$C$25,RTP分解!C16) -> 6 | D35: =IF($B$30=3,滚轴与赔付!$D$25,RTP分解!D16) -> 20 | E35: =IF($B$30=4,滚轴与赔付!$E$25,RTP分解!E16) -> 5 | F35: =IF($B$30=5,滚轴与赔付!$F$25,RTP分解!F16) -> 5 | G35: =滚轴与赔付!$E$25-E35 -> 15 | H35: =滚轴与赔付!$F$25-F35 -> 15 | I35: =滚轴与赔付!$F$25 -> 20 | J35: =B35*C35*D35*E35*F35 -> 12000 | K35: =B35*C35*D35*E35*H35 -> 36000 | L35: =B35*C35*D35*G35*I35 -> 144000 | M35: =VLOOKUP($A35,滚轴与赔付!$A$41:$D$45,4,FALSE()) -> 75 | N35: =VLOOKUP($A35,滚轴与赔付!$A$41:$D$45,3,FALSE()) -> 20 | O35: =VLOOKUP($A35,滚轴与赔付!$A$41:$D$45,2,FALSE()) -> 5 | P35: =RTP分解!$P$16 -> 0.1828125 | Q35: =(J35*M35+K35*N35+L35*O35)/滚轴与赔付!$H$25 -> 0.73125 | R35: =(1-$B$31)*P35+$B$31*Q35 -> 0.26507812
A36: 10 | B36: =IF($B$30=1,滚轴与赔付!$B$25,RTP分解!B17) -> 5 | C36: =IF($B$30=2,滚轴与赔付!$C$25,RTP分解!C17) -> 4 | D36: =IF($B$30=3,滚轴与赔付!$D$25,RTP分解!D17) -> 20 | E36: =IF($B$30=4,滚轴与赔付!$E$25,RTP分解!E17) -> 5 | F36: =IF($B$30=5,滚轴与赔付!$F$25,RTP分解!F17) -> 5 | G36: =滚轴与赔付!$E$25-E36 -> 15 | H36: =滚轴与赔付!$F$25-F36 -> 15 | I36: =滚轴与赔付!$F$25 -> 20 | J36: =B36*C36*D36*E36*F36 -> 10000 | K36: =B36*C36*D36*E36*H36 -> 30000 | L36: =B36*C36*D36*G36*I36 -> 120000 | M36: =VLOOKUP($A36,滚轴与赔付!$A$41:$D$45,4,FALSE()) -> 75 | N36: =VLOOKUP($A36,滚轴与赔付!$A$41:$D$45,3,FALSE()) -> 20 | O36: =VLOOKUP($A36,滚轴与赔付!$A$41:$D$45,2,FALSE()) -> 5 | P36: =RTP分解!$P$17 -> 0.15234375 | Q36: =(J36*M36+K36*N36+L36*O36)/滚轴与赔付!$H$25 -> 0.609375 | R36: =(1-$B$31)*P36+$B$31*Q36 -> 0.22089844
A37: 9 | B37: =IF($B$30=1,滚轴与赔付!$B$25,RTP分解!B18) -> 6 | C37: =IF($B$30=2,滚轴与赔付!$C$25,RTP分解!C18) -> 5 | D37: =IF($B$30=3,滚轴与赔付!$D$25,RTP分解!D18) -> 20 | E37: =IF($B$30=4,滚轴与赔付!$E$25,RTP分解!E18) -> 5 | F37: =IF($B$30=5,滚轴与赔付!$F$25,RTP分解!F18) -> 5 | G37: =滚轴与赔付!$E$25-E37 -> 15 | H37: =滚轴与赔付!$F$25-F37 -> 15 | I37: =滚轴与赔付!$F$25 -> 20 | J37: =B37*C37*D37*E37*F37 -> 15000 | K37: =B37*C37*D37*E37*H37 -> 45000 | L37: =B37*C37*D37*G37*I37 -> 180000 | M37: =VLOOKUP($A37,滚轴与赔付!$A$41:$D$45,4,FALSE()) -> 50 | N37: =VLOOKUP($A37,滚轴与赔付!$A$41:$D$45,3,FALSE()) -> 10 | O37: =VLOOKUP($A37,滚轴与赔付!$A$41:$D$45,2,FALSE()) -> 5 | P37: =RTP分解!$P$18 -> 0.1640625 | Q37: =(J37*M37+K37*N37+L37*O37)/滚轴与赔付!$H$25 -> 0.65625 | R37: =(1-$B$31)*P37+$B$31*Q37 -> 0.23789062
A38: 合计 | P38: =SUM(P33:P37) -> 0.59681875 | Q38: =SUM(Q33:Q37) -> 2.484875 | R38: =SUM(R33:R37) -> 0.88002719
A39: 相对基准（扩展前）的倍数 | C39: =R38/P38 -> 1.4745301
A41: 要点：整列变 WILD 时，该列对所有符号的匹配数 mᵢ 都等于 Nᵢ（必然命中），因此对 RTP 的拉动非常猛；实际项目通常只让扩展发生在轴 2/3/4，并压低触发率。
A43: 【三、黏性 WILD：Free Game 内逐局累积】
A44: 每局触发黏性的概率 p | B44: 0.12
A45: 黏住上限 k_max（格数） | B45: 3
A46: 免费局数 N | B46: 10
A47: 免费局 n | B47: 期望黏住 WILD 数 k_n | C47: 覆盖率 w = k_n | D47: 该局主游戏连线 RTP | E47: 相对基准倍数
A48: 1 | B48: =$B$45*(1-(1-$B$44)^A48) -> 0.36 | C48: =B48 -> 0.36 | D48: =SUMPRODUCT((首列WILD!$B$11:$B$15*(1-C48/20)+C48)*首列WILD!$O$11:$O$15)/滚轴与赔付!$H$25 -> 0.64119764 | E48: =D48/首列WILD!$C$21 -> 1.0743591
A49: 2 | B49: =$B$45*(1-(1-$B$44)^A49) -> 0.6768 | C49: =B49 -> 0.6768 | D49: =SUMPRODUCT((首列WILD!$B$11:$B$15*(1-C49/20)+C49)*首列WILD!$O$11:$O$15)/滚轴与赔付!$H$25 -> 0.68025106 | E49: =D49/首列WILD!$C$21 -> 1.1397951
...
