Workbook

Sheet 说明
A1: 运气工程 ④ —— Slots 游戏 RTP 计算规则 · ③免费篇
A3: 来源：知乎《Slots 游戏 RTP 计算规则 - ③免费篇》 https://zhuanlan.zhihu.com/p/1934736784882906672
A4: 专栏：运气工程：Slots 数值研究所 https://zhuanlan.zhihu.com/c_1918334633642287500
A6: 页签
A7: · 滚轴与计数：主游戏 / 免费游戏 两套转轮表与图案次数统计
A8: · 单把RTP：主游戏与免费游戏「一把」各自的 RTP（逐符号 5/4/3 连）
A9: · Scatter与触发率：Scatter 判定方式、主游戏触发率、免费游戏再触发率（枚举 16 种位置组合）
A10: · 免费游戏RTP：X = 1/(1 − Σ P'ₖ·Sₖ) → 平均总次数 → 免费 RTP → 总 RTP
A11: · 再触发与波动：再触发的放大倍数、一次免费游戏的期望返还、再触发率敏感性
A13: 一、本篇要解决的问题
A14: 1. Scatter 的概率到底怎么算？
A15: 2. 免费游戏的 RTP 怎么精确拆分？
... A23: 三、免费游戏的 RTP 计算流程
A24: 3.1
A25: 3.2
A26: 3.3
A27: 3.4
A28: 3.5
A29: 四、进阶设计：再触发与波动率影响
A30: 4.1
A31: 4.2
A32: 4.3
A33: 本簿按上述流程逐页落地：滚轴与计数 → 单把RTP（3.1 / 3.2）→ Scatter与触发率（2.1 / 2.2）→ 免费游戏RTP（3.3 / 3.4）→ 再触发与波动（4.1 / 4.2 / 4.3）。
A35: 二、Scatter 触发逻辑解析
A36: Scatter 图案是触发免费游戏（Free Game）的主要入口，它的判定方式与普通连线图案完全不同。
A37: 常见判定口径：
A38: · 任意位置计数：不看连线、不看行，只看出现在几根滚轴上（本簿按此口径）。
A39: · 按列计数：只看某一列是否出现（不看该列出现几个）。
A40: · 按个数计数：统计屏幕上 Scatter 的总个数。
A41: 本簿采用「任意位置计数」：某列只要在可见视窗里出现 ≥1 个 Scatter 即算命中该列，
A42: 因此单列命中概率 = 3 × (该列 Scatter 个数) ÷ (该列格数)。
A44: 三、触发率与再触发率
A45: · 主游戏触发率 Pₖ：主游戏一次 Spin 出现 k 个 Scatter（k = 3/4/5）的概率。
A46: 5
A47: · 免费游戏再触发率 P'ₖ：免费游戏中一次 Spin 出现 k 个 Scatter 的概率。
A48: 免费游戏的转轮表与主游戏不同（WILD 更多、滚轮 5 少一格），各列概率不再相等，
A49: 因此必须逐条枚举 C(5,3)=10、C(5,4)=5、C(5,5)=1 共 16 种位置组合后求和。
A51: 四、免费游戏的期望与 RTP 贡献公式
A52: · 单把免费游戏 RTP：算法与主游戏完全相同，只是换成免费游戏的转轮表。
A53: · X（1 个 Free Spin 含再触发后的平均 Spin 数）= 1 ÷ (1 − Σ P'ₖ·Sₖ)
...

Sheet 滚轴与计数
A1: 主游戏 / 免费游戏 两套转轮表与图案次数统计
A3: 【主游戏转轮表】每列 20 停（环绕带）
A4: 位置 | B4: 轮1 | C4: 轮2 | D4: 轮3 | E4: 轮4 | F4: 轮5
A5: 1 | B5: K | C5: K | D5: K | E5: K | F5: K
A6: 2 | B6: Q | C6: K | D6: K | E6: K | F6: K
A7: 3 | B7: Q | C7: K | D7: K | E7: K | F7: K
A8: 4 | B8: Q | C8: W | D8: W | E8: W | F8: W
A9: 5 | B9: J | C9: Q | D9: Q | E9: Q | F9: Q
A10: 6 | B10: J | C10: Q | D10: Q | E10: Q | F10: Q
A11: 7 | B11: J | C11: Q | D11: Q | E11: Q | F11: Q
A12: 8 | B12: J | C12: J | D12: J | E12: J | F12: J
A13: 9 | B13: 10 | C13: J | D13: J | E13: J | F13: J
A14: 10 | B14: 10 | C14: J | D14: J | E14: J | F14: J
A15: 11 | B15: 10 | C15: J | D15: J | E15: J | F15: J
A16: 12 | B16: 10 | C16: J | D16: 10 | E16: 10 | F16: 10
A17: 13 | B17: 10 | C17: 10 | D17: 10 | E17: 10 | F17: 10
A18: 14 | B18: 9 | C18: 10 | D18: 10 | E18: 10 | F18: 10
A19: 15 | B19: 9 | C19: 10 | D19: 10 | E19: 10 | F19: 10
A20: 16 | B20: 9 | C20: 9 | D20: 9 | E20: 9 | F20: 9
A21: 17 | B21: 9 | C21: 9 | D21: 9 | E21: 9 | F21: 9
A22: 18 | B22: 9 | C22: 9 | D22: 9 | E22: 9 | F22: 9
A23: 19 | B23: 9 | C23: 9 | D23: 9 | E23: 9 | F23: 9
A24: 20 | B24: S | C24: S | D24: S | E24: S | F24: S
A25: 每轮格数 | B25: =COUNTA(B5:B24) -> 20 | C25: =COUNTA(C5:C24) -> 20 | D25: =COUNTA(D5:D24) -> 20 | E25: =COUNTA(E5:E24) -> 20 | F25: =COUNTA(F5:F24) -> 20 | G25: 所有可能数 | H25: =PRODUCT(B25:F25) -> 3200000
A27: 图案次数统计
A28: 图案 | B28: 轮1 | C28: 轮2 | D28: 轮3 | E28: 轮4 | F28: 轮5
A29: any | B29: =B$25 -> 20 | C29: =C$25 -> 20 | D29: =D$25 -> 20 | E29: =E$25 -> 20 | F29: =F$25 -> 20
A30: W | B30: =COUNTIF(B$5:B$24,$A30) -> 0 | C30: =COUNTIF(C$5:C$24,$A30) -> 1 | D30: =COUNTIF(D$5:D$24,$A30) -> 1 | E30: =COUNTIF(E$5:E$24,$A30) -> 1 | F30: =COUNTIF(F$5:F$24,$A30) -> 1
A31: K | B31: =COUNTIF(B$5:B$24,$A31) -> 1 | C31: =COUNTIF(C$5:C$24,$A31) -> 3 | D31: =COUNTIF(D$5:D$24,$A31) -> 3 | E31: =COUNTIF(E$5:E$24,$A31) -> 3 | F31: =COUNTIF(F$5:F$24,$A31) -> 3
A32: Q | B32: =COUNTIF(B$5:B$24,$A32) -> 3 | C32: =COUNTIF(C$5:C$24,$A32) -> 3 | D32: =COUNTIF(D$5:D$24,$A32) -> 3 | E32: =COUNTIF(E$5:E$24,$A32) -> 3 | F32: =COUNTIF(F$5:F$24,$A32) -> 3
A33: J | B33: =COUNTIF(B$5:B$24,$A33) -> 4 | C33: =COUNTIF(C$5:C$24,$A33) -> 5 | D33: =COUNTIF(D$5:D$24,$A33) -> 4 | E33: =COUNTIF(E$5:E$24,$A33) -> 4 | F33: =COUNTIF(F$5:F$24,$A33) -> 4
A34: 10 | B34: =COUNTIF(B$5:B$24,$A34) -> 5 | C34: =COUNTIF(C$5:C$24,$A34) -> 3 | D34: =COUNTIF(D$5:D$24,$A34) -> 4 | E34: =COUNTIF(E$5:E$24,$A34) -> 4 | F34: =COUNTIF(F$5:F$24,$A34) -> 4
A35: 9 | B35: =COUNTIF(B$5:B$24,$A35) -> 6 | C35: =COUNTIF(C$5:C$24,$A35) -> 4 | D35: =COUNTIF(D$5:D$24,$A35) -> 4 | E35: =COUNTIF(E$5:E$24,$A35) -> 4 | F35: =COUNTIF(F$5:F$24,$A35) -> 4
A36: S | B36: =COUNTIF(B$5:B$24,$A36) -> 1 | C36: =COUNTIF(C$5:C$24,$A36) -> 1 | D36: =COUNTIF(D$5:D$24,$A36) -> 1 | E36: =COUNTIF(E$5:E$24,$A36) -> 1 | F36: =COUNTIF(F$5:F$24,$A36) -> 1
A37: 3S（3 行视窗 × Scatter 个数） | B37: =3*B36 -> 3 | C37: =3*C36 -> 3 | D37: =3*D36 -> 3 | E37: =3*E36 -> 3 | F37: =3*F36 -> 3
A39: 【免费游戏转轮表】WILD 变多；滚轮 5 少最后一格
A40: 位置 | B40: 轮1 | C40: 轮2 | D40: 轮3 | E40: 轮4 | F40: 轮5
A41: 1 | B41: K | C41: K | D41: K | E41: K | F41: K
A42: 2 | B42: Q | C42: K | D42: K | E42: K | F42: K
A43: 3 | B43: Q | C43: K | D43: K | E43: K | F43: K
...

Sheet 单把RTP
A1: 单把 RTP（逐符号 5/4/3 连 × 赔率 ÷ 所有可能数）
A3: 【主游戏单把 RTP】
A4: 符号 | B4: m1 | C4: m2 | D4: m3 | E4: m4 | F4: m5 | G4: X4 | H4: X5 | I4: N5 | J4: 5 | K4: 4 | L4: 3 | M4: 赔5 | N4: 赔4 | O4: 赔3 | P4: RTP贡献 | Q4: 备注
A5: K | B5: =滚轴与计数!B31+滚轴与计数!B$30 -> 1 | C5: =滚轴与计数!C31+滚轴与计数!C$30 -> 4 | D5: =滚轴与计数!D31+滚轴与计数!D$30 -> 4 | E5: =滚轴与计数!E31+滚轴与计数!E$30 -> 4 | F5: =滚轴与计数!F31+滚轴与计数!F$30 -> 4 | G5: =滚轴与计数!$E$25-E5 -> 16 | H5: =滚轴与计数!$F$25-F5 -> 16 | I5: =滚轴与计数!$F$25 -> 20 | J5: =B5*C5*D5*E5*F5 -> 256 | K5: =B5*C5*D5*E5*H5 -> 1024 | L5: =B5*C5*D5*G5*I5 -> 5120 | M5: =VLOOKUP($A5,滚轴与计数!$A$77:$D$81,4,FALSE()) -> 100 | N5: =VLOOKUP($A5,滚轴与计数!$A$77:$D$81,3,FALSE()) -> 30 | O5: =VLOOKUP($A5,滚轴与计数!$A$77:$D$81,2,FALSE()) -> 5 | P5: =(J5*M5+K5*N5+L5*O5)/滚轴与计数!$H$25 -> 0.0256
A6: Q | B6: =滚轴与计数!B32+滚轴与计数!B$30 -> 3 | C6: =滚轴与计数!C32+滚轴与计数!C$30 -> 4 | D6: =滚轴与计数!D32+滚轴与计数!D$30 -> 4 | E6: =滚轴与计数!E32+滚轴与计数!E$30 -> 4 | F6: =滚轴与计数!F32+滚轴与计数!F$30 -> 4 | G6: =滚轴与计数!$E$25-E6 -> 16 | H6: =滚轴与计数!$F$25-F6 -> 16 | I6: =滚轴与计数!$F$25 -> 20 | J6: =B6*C6*D6*E6*F6 -> 768 | K6: =B6*C6*D6*E6*H6 -> 3072 | L6: =B6*C6*D6*G6*I6 -> 15360 | M6: =VLOOKUP($A6,滚轴与计数!$A$77:$D$81,4,FALSE()) -> 100 | N6: =VLOOKUP($A6,滚轴与计数!$A$77:$D$81,3,FALSE()) -> 25 | O6: =VLOOKUP($A6,滚轴与计数!$A$77:$D$81,2,FALSE()) -> 5 | P6: =(J6*M6+K6*N6+L6*O6)/滚轴与计数!$H$25 -> 0.072
A7: J | B7: =滚轴与计数!B33+滚轴与计数!B$30 -> 4 | C7: =滚轴与计数!C33+滚轴与计数!C$30 -> 6 | D7: =滚轴与计数!D33+滚轴与计数!D$30 -> 5 | E7: =滚轴与计数!E33+滚轴与计数!E$30 -> 5 | F7: =滚轴与计数!F33+滚轴与计数!F$30 -> 5 | G7: =滚轴与计数!$E$25-E7 -> 15 | H7: =滚轴与计数!$F$25-F7 -> 15 | I7: =滚轴与计数!$F$25 -> 20 | J7: =B7*C7*D7*E7*F7 -> 3000 | K7: =B7*C7*D7*E7*H7 -> 9000 | L7: =B7*C7*D7*G7*I7 -> 36000 | M7: =VLOOKUP($A7,滚轴与计数!$A$77:$D$81,4,FALSE()) -> 75 | N7: =VLOOKUP($A7,滚轴与计数!$A$77:$D$81,3,FALSE()) -> 20 | O7: =VLOOKUP($A7,滚轴与计数!$A$77:$D$81,2,FALSE()) -> 5 | P7: =(J7*M7+K7*N7+L7*O7)/滚轴与计数!$H$25 -> 0.1828125
A8: 10 | B8: =滚轴与计数!B34+滚轴与计数!B$30 -> 5 | C8: =滚轴与计数!C34+滚轴与计数!C$30 -> 4 | D8: =滚轴与计数!D34+滚轴与计数!D$30 -> 5 | E8: =滚轴与计数!E34+滚轴与计数!E$30 -> 5 | F8: =滚轴与计数!F34+滚轴与计数!F$30 -> 5 | G8: =滚轴与计数!$E$25-E8 -> 15 | H8: =滚轴与计数!$F$25-F8 -> 15 | I8: =滚轴与计数!$F$25 -> 20 | J8: =B8*C8*D8*E8*F8 -> 2500 | K8: =B8*C8*D8*E8*H8 -> 7500 | L8: =B8*C8*D8*G8*I8 -> 30000 | M8: =VLOOKUP($A8,滚轴与计数!$A$77:$D$81,4,FALSE()) -> 75 | N8: =VLOOKUP($A8,滚轴与计数!$A$77:$D$81,3,FALSE()) -> 20 | O8: =VLOOKUP($A8,滚轴与计数!$A$77:$D$81,2,FALSE()) -> 5 | P8: =(J8*M8+K8*N8+L8*O8)/滚轴与计数!$H$25 -> 0.15234375
A9: 9 | B9: =滚轴与计数!B35+滚轴与计数!B$30 -> 6 | C9: =滚轴与计数!C35+滚轴与计数!C$30 -> 5 | D9: =滚轴与计数!D35+滚轴与计数!D$30 -> 5 | E9: =滚轴与计数!E35+滚轴与计数!E$30 -> 5 | F9: =滚轴与计数!F35+滚轴与计数!F$30 -> 5 | G9: =滚轴与计数!$E$25-E9 -> 15 | H9: =滚轴与计数!$F$25-F9 -> 15 | I9: =滚轴与计数!$F$25 -> 20 | J9: =B9*C9*D9*E9*F9 -> 3750 | K9: =B9*C9*D9*E9*H9 -> 11250 | L9: =B9*C9*D9*G9*I9 -> 45000 | M9: =VLOOKUP($A9,滚轴与计数!$A$77:$D$81,4,FALSE()) -> 50 | N9: =VLOOKUP($A9,滚轴与计数!$A$77:$D$81,3,FALSE()) -> 10 | O9: =VLOOKUP($A9,滚轴与计数!$A$77:$D$81,2,FALSE()) -> 5 | P9: =(J9*M9+K9*N9+L9*O9)/滚轴与计数!$H$25 -> 0.1640625
A10: 连线合计 | J10: =SUM(J5:J9) -> 10274 | K10: =SUM(K5:K9) -> 31846 | L10: =SUM(L5:L9) -> 131480 | M10: → 连线 RTP | P10: =SUM(P5:P9) -> 0.59681875
A11: 主游戏 Scatter 赔付 RTP | P11: =滚轴与计数!$B$82*Scatter与触发率!$D$21 -> 0.05322375
A12: 主游戏单把 RTP（连线 + Scatter） | P12: =P10+P11 -> 0.6500425 | Q12: ← 与 Part II 的 65.00% 一致
A14: 【免费游戏单把 RTP】
A15: 符号 | B15: m1 | C15: m2 | D15: m3 | E15: m4 | F15: m5 | G15: X4 | H15: X5 | I15: N5 | J15: 5 | K15: 4 | L15: 3 | M15: 赔5 | N15: 赔4 | O15: 赔3 | P15: RTP贡献 | Q15: 备注
A16: K | B16: =滚轴与计数!B67+滚轴与计数!B$66 -> 1 | C16: =滚轴与计数!C67+滚轴与计数!C$66 -> 5 | D16: =滚轴与计数!D67+滚轴与计数!D$66 -> 5 | E16: =滚轴与计数!E67+滚轴与计数!E$66 -> 5 | F16: =滚轴与计数!F67+滚轴与计数!F$66 -> 5 | G16: =滚轴与计数!$E$61-E16 -> 15 | H16: =滚轴与计数!$F$61-F16 -> 14 | I16: =滚轴与计数!$F$61 -> 19 | J16: =B16*C16*D16*E16*F16 -> 625 | K16: =B16*C16*D16*E16*H16 -> 1750 | L16: =B16*C16*D16*G16*I16 -> 7125 | M16: =VLOOKUP($A16,滚轴与计数!$A$77:$D$81,4,FALSE()) -> 100 | N16: =VLOOKUP($A16,滚轴与计数!$A$77:$D$81,3,FALSE()) -> 30 | O16: =VLOOKUP($A16,滚轴与计数!$A$77:$D$81,2,FALSE()) -> 5 | P16: =(J16*M16+K16*N16+L16*O16)/滚轴与计数!$H$61 -> 0.049547697
A17: Q | B17: =滚轴与计数!B68+滚轴与计数!B$66 -> 3 | C17: =滚轴与计数!C68+滚轴与计数!C$66 -> 4 | D17: =滚轴与计数!D68+滚轴与计数!D$66 -> 4 | E17: =滚轴与计数!E68+滚轴与计数!E$66 -> 4 | F17: =滚轴与计数!F68+滚轴与计数!F$66 -> 4 | G17: =滚轴与计数!$E$61-E17 -> 16 | H17: =滚轴与计数!$F$61-F17 -> 15 | I17: =滚轴与计数!$F$61 -> 19 | J17: =B17*C17*D17*E17*F17 -> 768 | K17: =B17*C17*D17*E17*H17 -> 2880 | L17: =B17*C17*D17*G17*I17 -> 14592 | M17: =VLOOKUP($A17,滚轴与计数!$A$77:$D$81,4,FALSE()) -> 100 | N17: =VLOOKUP($A17,滚轴与计数!$A$77:$D$81,3,FALSE()) -> 25 | O17: =VLOOKUP($A17,滚轴与计数!$A$77:$D$81,2,FALSE()) -> 5 | P17: =(J17*M17+K17*N17+L17*O17)/滚轴与计数!$H$61 -> 0.072947368
A18: J | B18: =滚轴与计数!B69+滚轴与计数!B$66 -> 4 | C18: =滚轴与计数!C69+滚轴与计数!C$66 -> 7 | D18: =滚轴与计数!D69+滚轴与计数!D$66 -> 6 | E18: =滚轴与计数!E69+滚轴与计数!E$66 -> 6 | F18: =滚轴与计数!F69+滚轴与计数!F$66 -> 6 | G18: =滚轴与计数!$E$61-E18 -> 14 | H18: =滚轴与计数!$F$61-F18 -> 13 | I18: =滚轴与计数!$F$61 -> 19 | J18: =B18*C18*D18*E18*F18 -> 6048 | K18: =B18*C18*D18*E18*H18 -> 13104 | L18: =B18*C18*D18*G18*I18 -> 44688 | M18: =VLOOKUP($A18,滚轴与计数!$A$77:$D$81,4,FALSE()) -> 75 | N18: =VLOOKUP($A18,滚轴与计数!$A$77:$D$81,3,FALSE()) -> 20 | O18: =VLOOKUP($A18,滚轴与计数!$A$77:$D$81,2,FALSE()) -> 5 | P18: =(J18*M18+K18*N18+L18*O18)/滚轴与计数!$H$61 -> 0.30892105
A19: 10 | B19: =滚轴与计数!B70+滚轴与计数!B$66 -> 5 | C19: =滚轴与计数!C70+滚轴与计数!C$66 -> 5 | D19: =滚轴与计数!D70+滚轴与计数!D$66 -> 6 | E19: =滚轴与计数!E70+滚轴与计数!E$66 -> 6 | F19: =滚轴与计数!F70+滚轴与计数!F$66 -> 6 | G19: =滚轴与计数!$E$61-E19 -> 14 | H19: =滚轴与计数!$F$61-F19 -> 13 | I19: =滚轴与计数!$F$61 -> 19 | J19: =B19*C19*D19*E19*F19 -> 5400 | K19: =B19*C19*D19*E19*H19 -> 11700 | L19: =B19*C19*D19*G19*I19 -> 39900 | M19: =VLOOKUP($A19,滚轴与计数!$A$77:$D$81,4,FALSE()) -> 75 | N19: =VLOOKUP($A19,滚轴与计数!$A$77:$D$81,3,FALSE()) -> 20 | O19: =VLOOKUP($A19,滚轴与计数!$A$77:$D$81,2,FALSE()) -> 5 | P19: =(J19*M19+K19*N19+L19*O19)/滚轴与计数!$H$61 -> 0.27582237
A20: 9 | B20: =滚轴与计数!B71+滚轴与计数!B$66 -> 6 | C20: =滚轴与计数!C71+滚轴与计数!C$66 -> 6 | D20: =滚轴与计数!D71+滚轴与计数!D$66 -> 6 | E20: =滚轴与计数!E71+滚轴与计数!E$66 -> 6 | F20: =滚轴与计数!F71+滚轴与计数!F$66 -> 5 | G20: =滚轴与计数!$E$61-E20 -> 14 | H20: =滚轴与计数!$F$61-F20 -> 14 | I20: =滚轴与计数!$F$61 -> 19 | J20: =B20*C20*D20*E20*F20 -> 6480 | K20: =B20*C20*D20*E20*H20 -> 18144 | L20: =B20*C20*D20*G20*I20 -> 57456 | M20: =VLOOKUP($A20,滚轴与计数!$A$77:$D$81,4,FALSE()) -> 50 | N20: =VLOOKUP($A20,滚轴与计数!$A$77:$D$81,3,FALSE()) -> 10 | O20: =VLOOKUP($A20,滚轴与计数!$A$77:$D$81,2,FALSE()) -> 5 | P20: =(J20*M20+K20*N20+L20*O20)/滚轴与计数!$H$61 -> 0.26076316
A21: 连线合计 | J21: =SUM(J16:J20) -> 19321 | K21: =SUM(K16:K20) -> 47578 | L21: =SUM(L16:L20) -> 163761 | M21: → 连线 RTP | P21: =SUM(P16:P20) -> 0.96800164
A22: 免费游戏 Scatter 赔付 RTP | P22: =Scatter与触发率!$C$58 -> 0.054763816
A23: 单把免费游戏 RTP（连线 + Scatter） | P23: =P21+P22 -> 1.0227655 | Q23: ← 与 Part II 的 102.2765% 一致

Sheet Scatter与触发率
A1: Scatter 判定方式 / 主游戏触发率 / 免费游戏再触发率
A3: 【Scatter 的三种常见判定方式】
A4: ① 任意位置计数：只要出现在 ≥3 根滚轴上即触发（不看连线、不看行）—— 本簿口径
A5: ② 按列计数：只看该列是否出现（不看该列出现几个）
A6: ③ 按个数计数：统计屏幕上 Scatter 的总个数（≥3 个即触发）
A7: 本簿口径下单列命中概率 p = 3 × (该列 Scatter 个数) ÷ (该列格数)
A9: 【一、主游戏 Scatter 概率与触发率】
A10: 项目 | B10: 轮1 | C10: 轮2 | D10: 轮3 | E10: 轮4 | F10: 轮5
A11: 每列格数 N | B11: =滚轴与计数!B$25 -> 20 | C11: =滚轴与计数!C$25 -> 20 | D11: =滚轴与计数!D$25 -> 20 | E11: =滚轴与计数!E$25 -> 20 | F11: =滚轴与计数!F$25 -> 20
A12: 每列 Scatter 个数 s | B12: =滚轴与计数!B$36 -> 1 | C12: =滚轴与计数!C$36 -> 1 | D12: =滚轴与计数!D$36 -> 1 | E12: =滚轴与计数!E$36 -> 1 | F12: =滚轴与计数!F$36 -> 1
A13: 3S = 3 × s（可见视窗里出现 Scatter 的窗口数） | B13: =3*B12 -> 3 | C13: =3*C12 -> 3 | D13: =3*D12 -> 3 | E13: =3*E12 -> 3 | F13: =3*F12 -> 3
A14: X_3S = N − 3S（无 Scatter 的窗口数） | B14: =B11-B13 -> 17 | C14: =C11-C13 -> 17 | D14: =D11-D13 -> 17 | E14: =E11-E13 -> 17 | F14: =F11-F13 -> 17
A15: 单列命中概率 p = 3S / N | B15: =B13/B11 -> 0.15 | C15: =C13/C11 -> 0.15 | D15: =D13/D11 -> 0.15 | E15: =E13/E11 -> 0.15 | F15: =F13/F11 -> 0.15
A17: Scatter 个数 k | B17: 位置组合数 C(5,k) | C17: 单条组合概率 | D17: 主游戏触发率 Pₖ | E17: 触发时发放次数 Sₖ | F17: 平均发放次数 Pₖ·Sₖ
A18: 3 | B18: 10 | C18: =$B$15^A18*(1-$B$15)^(5-A18) -> 0.0024384375 | D18: =B18*C18 -> 0.024384375 | E18: 10 | F18: =D18*E18 -> 0.24384375
A19: 4 | B19: 5 | C19: =$B$15^A19*(1-$B$15)^(5-A19) -> 0.0004303125 | D19: =B19*C19 -> 0.0021515625 | E19: 15 | F19: =D19*E19 -> 0.032273438
A20: 5 | B20: 1 | C20: =$B$15^A20*(1-$B$15)^(5-A20) -> 7.59375e-05 | D20: =B20*C20 -> 7.59375e-05 | E20: 20 | F20: =D20*E20 -> 0.00151875
A21: 合计 | D21: =SUM(D18:D20) -> 0.026611875 | F21: =SUM(F18:F20) -> 0.27763594 | G21: 触发 ≥3 个 Scatter 的总概率
A23: 【二、免费游戏 Scatter 概率】
A24: 项目 | B24: 轮1 | C24: 轮2 | D24: 轮3 | E24: 轮4 | F24: 轮5
A25: 每列格数 N | B25: =滚轴与计数!B$61 -> 20 | C25: =滚轴与计数!C$61 -> 20 | D25: =滚轴与计数!D$61 -> 20 | E25: =滚轴与计数!E$61 -> 20 | F25: =滚轴与计数!F$61 -> 19
A26: 每列 Scatter 个数 s | B26: =滚轴与计数!B$72 -> 1 | C26: =滚轴与计数!C$72 -> 1 | D26: =滚轴与计数!D$72 -> 1 | E26: =滚轴与计数!E$72 -> 1 | F26: =滚轴与计数!F$72 -> 1
A27: 3S = 3 × s | B27: =3*B26 -> 3 | C27: =3*C26 -> 3 | D27: =3*D26 -> 3 | E27: =3*E26 -> 3 | F27: =3*F26 -> 3
A28: X_3S = N − 3S | B28: =B25-B27 -> 17 | C28: =C25-C27 -> 17 | D28: =D25-D27 -> 17 | E28: =E25-E27 -> 17 | F28: =F25-F27 -> 16
A29: 单列命中概率 p' = 3S / N | B29: =B27/B25 -> 0.15 | C29: =C27/C25 -> 0.15 | D29: =D27/D25 -> 0.15 | E29: =E27/E25 -> 0.15 | F29: =F27/F25 -> 0.15789474
A31: 【三、免费游戏再触发率：枚举 16 种位置组合】
A32: 序号 | B32: 轮1 | C32: 轮2 | D32: 轮3 | E32: 轮4 | F32: 轮5 | G32: 命中个数 k | H32: 组合概率
A33: 1 | B33: 1 | C33: 1 | D33: 1 | E33: 0 | F33: 0 | G33: =SUM(B33:F33) -> 3 | H33: =IF(B33=1,$B$29,1-$B$29)*IF(C33=1,$C$29,1-$C$29)*IF(D33=1,$D$29,1-$D$29)*IF(E33=1,$E$29,1-$E$29)*IF(F33=1,$F$29,1-$F$29) -> 0.0024157895
A34: 2 | B34: 1 | C34: 1 | D34: 0 | E34: 1 | F34: 0 | G34: =SUM(B34:F34) -> 3 | H34: =IF(B34=1,$B$29,1-$B$29)*IF(C34=1,$C$29,1-$C$29)*IF(D34=1,$D$29,1-$D$29)*IF(E34=1,$E$29,1-$E$29)*IF(F34=1,$F$29,1-$F$29) -> 0.0024157895
A35: 3 | B35: 1 | C35: 1 | D35: 0 | E35: 0 | F35: 1 | G35: =SUM(B35:F35) -> 3 | H35: =IF(B35=1,$B$29,1-$B$29)*IF(C35=1,$C$29,1-$C$29)*IF(D35=1,$D$29,1-$D$29)*IF(E35=1,$E$29,1-$E$29)*IF(F35=1,$F$29,1-$F$29) -> 0.0025667763
A36: 4 | B36: 1 | C36: 0 | D36: 1 | E36: 1 | F36: 0 | G36: =SUM(B36:F36) -> 3 | H36: =IF(B36=1,$B$29,1-$B$29)*IF(C36=1,$C$29,1-$C$29)*IF(D36=1,$D$29,1-$D$29)*IF(E36=1,$E$29,1-$E$29)*IF(F36=1,$F$29,1-$F$29) -> 0.0024157895
A37: 5 | B37: 1 | C37: 0 | D37: 1 | E37: 0 | F37: 1 | G37: =SUM(B37:F37) -> 3 | H37: =IF(B37=1,$B$29,1-$B$29)*IF(C37=1,$C$29,1-$C$29)*IF(D37=1,$D$29,1-$D$29)*IF(E37=1,$E$29,1-$E$29)*IF(F37=1,$F$29,1-$F$29) -> 0.0025667763
A38: 6 | B38: 1 | C38: 0 | D38: 0 | E38: 1 | F38: 1 | G38: =SUM(B38:F38) -> 3 | H38: =IF(B38=1,$B$29,1-$B$29)*IF(C38=1,$C$29,1-$C$29)*IF(D38=1,$D$29,1-$D$29)*IF(E38=1,$E$29,1-$E$29)*IF(F38=1,$F$29,1-$F$29) -> 0.0025667763
A39: 7 | B39: 0 | C39: 1 | D39: 1 | E39: 1 | F39: 0 | G39: =SUM(B39:F39) -> 3 | H39: =IF(B39=1,$B$29,1-$B$29)*IF(C39=1,$C$29,1-$C$29)*IF(D39=1,$D$29,1-$D$29)*IF(E39=1,$E$29,1-$E$29)*IF(F39=1,$F$29,1-$F$29) -> 0.0024157895
A40: 8 | B40: 0 | C40: 1 | D40: 1 | E40: 0 | F40: 1 | G40: =SUM(B40:F40) -> 3 | H40: =IF(B40=1,$B$29,1-$B$29)*IF(C40=1,$C$29,1-$C$29)*IF(D40=1,$D$29,1-$D$29)*IF(E40=1,$E$29,1-$E$29)*IF(F40=1,$F$29,1-$F$29) -> 0.0025667763
A41: 9 | B41: 0 | C41: 1 | D41: 0 | E41: 1 | F41: 1 | G41: =SUM(B41:F41) -> 3 | H41: =IF(B41=1,$B$29,1-$B$29)*IF(C41=1,$C$29,1-$C$29)*IF(D41=1,$D$29,1-$D$29)*IF(E41=1,$E$29,1-$E$29)*IF(F41=1,$F$29,1-$F$29) -> 0.0025667763
A42: 10 | B42: 0 | C42: 0 | D42: 1 | E42: 1 | F42: 1 | G42: =SUM(B42:F42) -> 3 | H42: =IF(B42=1,$B$29,1-$B$29)*IF(C42=1,$C$29,1-$C$29)*IF(D42=1,$D$29,1-$D$29)*IF(E42=1,$E$29,1-$E$29)*IF(F42=1,$F$29,1-$F$29) -> 0.0025667763
A43: 11 | B43: 1 | C43: 1 | D43: 1 | E43: 1 | F43: 0 | G43: =SUM(B43:F43) -> 4 | H43: =IF(B43=1,$B$29,1-$B$29)*IF(C43=1,$C$29,1-$C$29)*IF(D43=1,$D$29,1-$D$29)*IF(E43=1,$E$29,1-$E$29)*IF(F43=1,$F$29,1-$F$29) -> 0.00042631579
A44: 12 | B44: 1 | C44: 1 | D44: 1 | E44: 0 | F44: 1 | G44: =SUM(B44:F44) -> 4 | H44: =IF(B44=1,$B$29,1-$B$29)*IF(C44=1,$C$29,1-$C$29)*IF(D44=1,$D$29,1-$D$29)*IF(E44=1,$E$29,1-$E$29)*IF(F44=1,$F$29,1-$F$29) -> 0.00045296053
... A48: 16 | B48: 1 | C48: 1 | D48: 1 | E48: 1 | F48: 1 | G48: =SUM(B48:F48) -> 5 | H48: =IF(B48=1,$B$29,1-$B$29)*IF(C48=1,$C$29,1-$C$29)*IF(D48=1,$D$29,1-$D$29)*IF(E48=1,$E$29,1-$E$29)*IF(F48=1,$F$29,1-$F$29) -> 7.9934211e-05
...

Sheet 免费游戏RTP
A1: 免费游戏 RTP 与总 RTP（含再触发）
A3: 【触发率 / 再触发率 / 免费次数】
A4: 项目 | B4: 3 | C4: 4 | D4: 5 | E4: 说明
A5: 主游戏触发率 Pₖ | B5: =Scatter与触发率!$D$18 -> 0.024384375 | C5: =Scatter与触发率!$D$19 -> 0.0021515625 | D5: =Scatter与触发率!$D$20 -> 7.59375e-05
A6: 免费游戏再触发率 P'ₖ | B6: =Scatter与触发率!$C$52 -> 0.025063816 | C6: =Scatter与触发率!$C$53 -> 0.0022381579 | D6: =Scatter与触发率!$C$54 -> 7.9934211e-05
A7: 触发时发放的免费次数 Sₖ | B7: =Scatter与触发率!$E$18 -> 10 | C7: =Scatter与触发率!$E$19 -> 15 | D7: =Scatter与触发率!$E$20 -> 20
A8: 再触发增发次数贡献 P'ₖ·Sₖ | B8: =B6*B7 -> 0.25063816 | C8: =C6*C7 -> 0.033572368 | D8: =D6*D7 -> 0.0015986842
A10: Σ P'ₖ·Sₖ（必须 < 1） | B10: =SUM(B8:D8) -> 0.28580921
A11: X = 1 个 Free Spin 含再触发后的平均 Spin 数 | B11: =1/(1-B10) -> 1.4001861
A12: 免费游戏平均总次数 = Sₖ × X | B12: =B7*$B$11 -> 14.001861 | C12: =C7*$B$11 -> 21.002791 | D12: =D7*$B$11 -> 28.003722
A14: 【免费游戏 RTP】
A15: 单把免费游戏 RTP | B15: =单把RTP!$P$23 -> 1.0227655
A16: 项目 | B16: 3 | C16: 4 | D16: 5 | E16: 公式
A17: 免费游戏 RTP（k 个 Scatter） | B17: =B5*$B$15*B12 -> 0.34919936 | C17: =C5*$B$15*C12 -> 0.046217562 | D17: =D5*$B$15*D12 -> 0.0021749441 | E17: 公式：Pₖ × 单把免费RTP × 平均总次数
A18: 免费游戏 RTP 合计 | B18: =SUM(B17:D17) -> 0.39759186
A20: 【总 RTP】
A21: 主游戏 RTP | B21: =单把RTP!$P$12 -> 0.6500425
A22: 免费游戏 RTP | B22: =B18 -> 0.39759186
A23: 总 RTP = 主游戏 + 免费游戏 | B23: =B21+B22 -> 1.0476344
A25: 【原文 / 参考簿对照】
A26: 主游戏 RTP（Part II） | B26: 0.6500425
A27: 单把免费游戏 RTP（Part II） | B27: 1.0227655
A28: X（Part II） | B28: 1.4001861
A29: 免费游戏 RTP（Part II） | B29: 0.39759186
A30: 总 RTP（Part II） | B30: 1.0476344
A31: 本簿 X 与 Part II 的差 | B31: =B11-B28 -> -2.6397193e-09
A32: 本簿总 RTP 与 Part II 的差 | B32: =B23-B30 -> 4.3323611e-09
A33: 注：原文与 Part II 的总 RTP 超过 100%，属教学示例（便于看清各项贡献）；商业机台会把各模块下调到 95% 上下的目标值。

Sheet 再触发与波动
A1: 再触发机制对免费次数与波动率的影响
A3: 【再触发的放大倍数】
A4: X（含再触发的平均倍数） | B4: =免费游戏RTP!$B$11 -> 1.4001861
A5: X − 1（再触发带来的额外倍数） | B5: =B4-1 -> 0.40018608
A6: 再触发贡献占免费 RTP 的比例 | B6: =B5/B4 -> 0.28580921
A7: 无再触发时（X=1）免费游戏 RTP | B7: =免费游戏RTP!$B$18/免费游戏RTP!$B$11 -> 0.28395645 | E7: ← 与含再触发对比即得再触发的绝对贡献
A9: 【一次免费游戏的期望返还倍数（波动代理）】
A10: 触发情形 | B10: 初始次数 Sₖ | C10: 平均总次数 | D10: 单把免费 RTP | E10: 一次免费游戏期望返还倍数 | F10: 说明
A11: 3 | B11: =免费游戏RTP!B7 -> 10 | C11: =免费游戏RTP!B12 -> 14.001861 | D11: =免费游戏RTP!$B$15 -> 1.0227655 | E11: =C11*D11 -> 14.32062
A12: 4 | B12: =免费游戏RTP!C7 -> 15 | C12: =免费游戏RTP!C12 -> 21.002791 | D12: =免费游戏RTP!$B$15 -> 1.0227655 | E12: =C12*D12 -> 21.480929
A13: 5 | B13: =免费游戏RTP!D7 -> 20 | C13: =免费游戏RTP!D12 -> 28.003722 | D13: =免费游戏RTP!$B$15 -> 1.0227655 | E13: =C13*D13 -> 28.641239 | F13: 5
A15: 【再触发率敏感性：缩放 Σ P'ₖ·Sₖ】
A16: 再触发率缩放 k | B16: Σ P'ₖ·Sₖ (×k) | C16: X | D16: 免费游戏 RTP 合计 | E16: 总 RTP | F16: 风险提示
A17: 0 | B17: =A17*免费游戏RTP!$B$10 -> 0 | C17: =IF(B17>=1,"发散",1/(1-B17)) -> 1 | D17: =IF(B17>=1,"",(免费游戏RTP!$B$17+免费游戏RTP!$C$17+免费游戏RTP!$D$17)*(1/(1-B17))/免费游戏RTP!$B$11) -> 0.28395645 | E17: =IF(B17>=1,"",免费游戏RTP!$B$21+D17) -> 0.93399895 | F17: 不设再触发：X = 1，波动最低
A18: 0.25 | B18: =A18*免费游戏RTP!$B$10 -> 0.071452303 | C18: =IF(B18>=1,"发散",1/(1-B18)) -> 1.0769506 | D18: =IF(B18>=1,"",(免费游戏RTP!$B$17+免费游戏RTP!$C$17+免费游戏RTP!$D$17)*(1/(1-B18))/免费游戏RTP!$B$11) -> 0.30580707 | E18: =IF(B18>=1,"",免费游戏RTP!$B$21+D18) -> 0.95584957
A19: 0.5 | B19: =A19*免费游戏RTP!$B$10 -> 0.14290461 | C19: =IF(B19>=1,"发散",1/(1-B19)) -> 1.1667313 | D19: =IF(B19>=1,"",(免费游戏RTP!$B$17+免费游戏RTP!$C$17+免费游戏RTP!$D$17)*(1/(1-B19))/免费游戏RTP!$B$11) -> 0.33130087 | E19: =IF(B19>=1,"",免费游戏RTP!$B$21+D19) -> 0.98134337
A20: 0.75 | B20: =A20*免费游戏RTP!$B$10 -> 0.21435691 | C20: =IF(B20>=1,"发散",1/(1-B20)) -> 1.2728426 | D20: =IF(B20>=1,"",(免费游戏RTP!$B$17+免费游戏RTP!$C$17+免费游戏RTP!$D$17)*(1/(1-B20))/免费游戏RTP!$B$11) -> 0.36143186 | E20: =IF(B20>=1,"",免费游戏RTP!$B$21+D20) -> 1.0114744
A21: 1 | B21: =A21*免费游戏RTP!$B$10 -> 0.28580921 | C21: =IF(B21>=1,"发散",1/(1-B21)) -> 1.4001861 | D21: =IF(B21>=1,"",(免费游戏RTP!$B$17+免费游戏RTP!$C$17+免费游戏RTP!$D$17)*(1/(1-B21))/免费游戏RTP!$B$11) -> 0.39759186 | E21: =IF(B21>=1,"",免费游戏RTP!$B$21+D21) -> 1.0476344 | F21: 本簿基准
A22: 1.25 | B22: =A22*免费游戏RTP!$B$10 -> 0.35726151 | C22: =IF(B22>=1,"发散",1/(1-B22)) -> 1.5558427 | D22: =IF(B22>=1,"",(免费游戏RTP!$B$17+免费游戏RTP!$C$17+免费游戏RTP!$D$17)*(1/(1-B22))/免费游戏RTP!$B$11) -> 0.44179157 | E22: =IF(B22>=1,"",免费游戏RTP!$B$21+D22) -> 1.0918341
A23: 1.5 | B23: =A23*免费游戏RTP!$B$10 -> 0.42871382 | C23: =IF(B23>=1,"发散",1/(1-B23)) -> 1.7504362 | D23: =IF(B23>=1,"",(免费游戏RTP!$B$17+免费游戏RTP!$C$17+免费游戏RTP!$D$17)*(1/(1-B23))/免费游戏RTP!$B$11) -> 0.49704764 | E23: =IF(B23>=1,"",免费游戏RTP!$B$21+D23) -> 1.1470901 | F23: ΣP'S ≥ 1 时 X 发散，免费转停不下来
A24: 2 | B24: =A24*免费游戏RTP!$B$10 -> 0.57161842 | C24: =IF(B24>=1,"发散",1/(1-B24)) -> 2.3343674 | D24: =IF(B24>=1,"",(免费游戏RTP!$B$17+免费游戏RTP!$C$17+免费游戏RTP!$D$17)*(1/(1-B24))/免费游戏RTP!$B$11) -> 0.66285868 | E24: =IF(B24>=1,"",免费游戏RTP!$B$21+D24) -> 1.3129012 | F24: ΣP'S ≥ 1 时 X 发散，免费转停不下来
A26: 工程口径：Σ P'ₖ·Sₖ 建议控制在 0.3 以下（即 X ≤ 1.43），并对「单次触发的免费转总数」加硬上限兜底。
