Workbook

Sheet 说明
A1: 运气工程 ③ —— Slots 游戏 RTP 计算规则 · ②基础篇
A3: 来源：知乎《Slots 游戏 RTP 计算规则 - ②基础篇》 https://zhuanlan.zhihu.com/p/1927429615065995087
A4: 专栏：运气工程：Slots 数值研究所 https://zhuanlan.zhihu.com/c_1918334633642287500
A6: 页签
A7: · 滚轴与赔付：3 行 × 5 列 示例滚轴 / 图案次数统计 / 赔付表 / 5 条线的线型定义
A8: · 线型与RTP：由滚轴 + 赔付表逐符号算出「单线 RTP」，并说明各线统计相同
A9: · 线注与可选线：线数 ↔ 线注 ↔ 记账比例的换算；玩家只买 n 条线时的中奖率与 RTP
A10: · 满线Ways：243 / 1024 / 3125 ways 与有线的关系
A11: · 易错点-窗口环绕：滚轴是否环绕对「每一行」计数的影响
A13: 一、滚轴线数的规则
A14: · 有线（Lines Slots）：最经典的 Slots，由固定 paylines（赔付线）构成。
A15: 示例游戏 GOP3：3 行 5 列的经典滚轴结构。
... A38: Xᵢ = Nᵢ − mᵢ（Nᵢ = 该列格数），则：
A39: 5
A40: 4
A41: 3
A42: RTP 贡献 = (5连×赔5 + 4连×赔4 + 3连×赔3) ÷ 所有可能数
A43: 所有可能数 = Π Nᵢ = 20⁵ = 3,200,000。
A45: 五、抓取说明
A46: 原文摘要：本文将系统性地拆解以下基础设计要素 —— 滚轴线数规则（包括满线、有线、ways 等不同模式）、
A47: WILD 百搭机制的特殊规则、SCATTER 触发机制的实现原理，以及滚轴配置的基础方法；
A48: 通过对这些核心要素的逐步解析，完整展现它们如何共同影响 Slots 的 RTP，
A49: 并最终通过具体的数值计算表格来验证设计的合理性。
A50: 原文目录：一、滚轴线数的规则（有线 / 满线 / 可选线）；二、赔付表；WILD 百搭机制；SCATTER 触发机制；最后用数值表算滚轴 RTP。
A51: 原文配图（示例游戏 GOP3 的 3×5 滚轴截图等）未能读取，滚轴与赔付表沿用同目录 Part II 的示例数值。
A52: 蓝色 = 可改输入；黑色 = 公式；黄底 = 关键结果。

Sheet 滚轴与赔付
A1: 3
A3: 【转轮表】每列 20 停（环绕带）—— 蓝字可改
A4: 位置 | B4: 轮1 | C4: 轮2 | D4: 轮3 | E4: 轮4 | F4: 轮5
A5: 1 | B5: K | C5: K | D5: K | E5: K | F5: K
A6: 2 | B6: Q | C6: K | D6: K | E6: K | F6: K
A7: 3 | B7: Q | C7: K | D7: K | E7: K | F7: K
A8: 4 | B8: Q | C8: W | D8: W | E8: W | F8: W
A9: 5 | B9: J | C9: Q | D9: Q | E9: Q | F9: Q
A10: 6 | B10: J | C10: Q | D10: Q | E10: Q | F10: Q
A11: 7 | B11: J | C11: Q | D11: Q | E11: Q | F11: Q
A12: 8 | B12: J | C12: J | D12: J | E12: J | F12: J
A13: 9 | B13: 10 | C13: J | D13: J | E13: J | F13: J
A14: 10 | B14: 10 | C14: J | D14: J | E14: J | F14: J
A15: 11 | B15: 10 | C15: J | D15: J | E15: J | F15: J
A16: 12 | B16: 10 | C16: J | D16: 10 | E16: 10 | F16: 10
A17: 13 | B17: 10 | C17: 10 | D17: 10 | E17: 10 | F17: 10
A18: 14 | B18: 9 | C18: 10 | D18: 10 | E18: 10 | F18: 10
A19: 15 | B19: 9 | C19: 10 | D19: 10 | E19: 10 | F19: 10
A20: 16 | B20: 9 | C20: 9 | D20: 9 | E20: 9 | F20: 9
A21: 17 | B21: 9 | C21: 9 | D21: 9 | E21: 9 | F21: 9
A22: 18 | B22: 9 | C22: 9 | D22: 9 | E22: 9 | F22: 9
A23: 19 | B23: 9 | C23: 9 | D23: 9 | E23: 9 | F23: 9
A24: 20 | B24: S | C24: S | D24: S | E24: S | F24: S
A25: 每轮格数 | B25: =COUNTA(B5:B24) -> 20 | C25: =COUNTA(C5:C24) -> 20 | D25: =COUNTA(D5:D24) -> 20 | E25: =COUNTA(E5:E24) -> 20 | F25: =COUNTA(F5:F24) -> 20 | G25: 所有可能数 | H25: =PRODUCT(B25:F25) -> 3200000
A27: 【图案次数统计】
A28: 图案 | B28: 轮1 | C28: 轮2 | D28: 轮3 | E28: 轮4 | F28: 轮5
A29: any | B29: =B$25 -> 20 | C29: =C$25 -> 20 | D29: =D$25 -> 20 | E29: =E$25 -> 20 | F29: =F$25 -> 20
A30: W | B30: =COUNTIF(B$5:B$24,$A30) -> 0 | C30: =COUNTIF(C$5:C$24,$A30) -> 1 | D30: =COUNTIF(D$5:D$24,$A30) -> 1 | E30: =COUNTIF(E$5:E$24,$A30) -> 1 | F30: =COUNTIF(F$5:F$24,$A30) -> 1
A31: K | B31: =COUNTIF(B$5:B$24,$A31) -> 1 | C31: =COUNTIF(C$5:C$24,$A31) -> 3 | D31: =COUNTIF(D$5:D$24,$A31) -> 3 | E31: =COUNTIF(E$5:E$24,$A31) -> 3 | F31: =COUNTIF(F$5:F$24,$A31) -> 3
A32: Q | B32: =COUNTIF(B$5:B$24,$A32) -> 3 | C32: =COUNTIF(C$5:C$24,$A32) -> 3 | D32: =COUNTIF(D$5:D$24,$A32) -> 3 | E32: =COUNTIF(E$5:E$24,$A32) -> 3 | F32: =COUNTIF(F$5:F$24,$A32) -> 3
A33: J | B33: =COUNTIF(B$5:B$24,$A33) -> 4 | C33: =COUNTIF(C$5:C$24,$A33) -> 5 | D33: =COUNTIF(D$5:D$24,$A33) -> 4 | E33: =COUNTIF(E$5:E$24,$A33) -> 4 | F33: =COUNTIF(F$5:F$24,$A33) -> 4
A34: 10 | B34: =COUNTIF(B$5:B$24,$A34) -> 5 | C34: =COUNTIF(C$5:C$24,$A34) -> 3 | D34: =COUNTIF(D$5:D$24,$A34) -> 4 | E34: =COUNTIF(E$5:E$24,$A34) -> 4 | F34: =COUNTIF(F$5:F$24,$A34) -> 4
A35: 9 | B35: =COUNTIF(B$5:B$24,$A35) -> 6 | C35: =COUNTIF(C$5:C$24,$A35) -> 4 | D35: =COUNTIF(D$5:D$24,$A35) -> 4 | E35: =COUNTIF(E$5:E$24,$A35) -> 4 | F35: =COUNTIF(F$5:F$24,$A35) -> 4
A36: S | B36: =COUNTIF(B$5:B$24,$A36) -> 1 | C36: =COUNTIF(C$5:C$24,$A36) -> 1 | D36: =COUNTIF(D$5:D$24,$A36) -> 1 | E36: =COUNTIF(E$5:E$24,$A36) -> 1 | F36: =COUNTIF(F$5:F$24,$A36) -> 1
A37: 3S（3 行视窗 × Scatter 个数） | B37: =3*B36 -> 3 | C37: =3*C36 -> 3 | D37: =3*D36 -> 3 | E37: =3*E36 -> 3 | F37: =3*F36 -> 3
A39: 【赔付表】列 = 连线数；S 行为「每个 Scatter」的得分
A40: 图案 | B40: 3 | C40: 4 | D40: 5
A41: K | B41: 5 | C41: 30 | D41: 100
A42: Q | B42: 5 | C42: 25 | D42: 100
A43: J | B43: 5 | C43: 20 | D43: 75
...

Sheet 线型与RTP
A1: 单线 RTP = Σ 逐符号(5连 / 4连 / 3连 出现次数 × 赔率) ÷ 所有可能数
A3: 【逐符号计算】mᵢ = 第 i 列该符号数 + WILD 数；Xᵢ = Nᵢ − mᵢ
A4: 符号 | B4: m1 | C4: m2 | D4: m3 | E4: m4 | F4: m5 | G4: X4 | H4: X5 | I4: N5 | J4: 5 | K4: 4 | L4: 3 | M4: 赔5 | N4: 赔4 | O4: 赔3 | P4: RTP贡献 | Q4: 备注
A5: K | B5: =滚轴与赔付!B31+滚轴与赔付!B$30 -> 1 | C5: =滚轴与赔付!C31+滚轴与赔付!C$30 -> 4 | D5: =滚轴与赔付!D31+滚轴与赔付!D$30 -> 4 | E5: =滚轴与赔付!E31+滚轴与赔付!E$30 -> 4 | F5: =滚轴与赔付!F31+滚轴与赔付!F$30 -> 4 | G5: =滚轴与赔付!$E$25-E5 -> 16 | H5: =滚轴与赔付!$F$25-F5 -> 16 | I5: =滚轴与赔付!$F$25 -> 20 | J5: =B5*C5*D5*E5*F5 -> 256 | K5: =B5*C5*D5*E5*H5 -> 1024 | L5: =B5*C5*D5*G5*I5 -> 5120 | M5: =VLOOKUP($A5,滚轴与赔付!$A$41:$D$45,4,FALSE()) -> 100 | N5: =VLOOKUP($A5,滚轴与赔付!$A$41:$D$45,3,FALSE()) -> 30 | O5: =VLOOKUP($A5,滚轴与赔付!$A$41:$D$45,2,FALSE()) -> 5 | P5: =(J5*M5+K5*N5+L5*O5)/滚轴与赔付!$H$25 -> 0.0256
A6: Q | B6: =滚轴与赔付!B32+滚轴与赔付!B$30 -> 3 | C6: =滚轴与赔付!C32+滚轴与赔付!C$30 -> 4 | D6: =滚轴与赔付!D32+滚轴与赔付!D$30 -> 4 | E6: =滚轴与赔付!E32+滚轴与赔付!E$30 -> 4 | F6: =滚轴与赔付!F32+滚轴与赔付!F$30 -> 4 | G6: =滚轴与赔付!$E$25-E6 -> 16 | H6: =滚轴与赔付!$F$25-F6 -> 16 | I6: =滚轴与赔付!$F$25 -> 20 | J6: =B6*C6*D6*E6*F6 -> 768 | K6: =B6*C6*D6*E6*H6 -> 3072 | L6: =B6*C6*D6*G6*I6 -> 15360 | M6: =VLOOKUP($A6,滚轴与赔付!$A$41:$D$45,4,FALSE()) -> 100 | N6: =VLOOKUP($A6,滚轴与赔付!$A$41:$D$45,3,FALSE()) -> 25 | O6: =VLOOKUP($A6,滚轴与赔付!$A$41:$D$45,2,FALSE()) -> 5 | P6: =(J6*M6+K6*N6+L6*O6)/滚轴与赔付!$H$25 -> 0.072
A7: J | B7: =滚轴与赔付!B33+滚轴与赔付!B$30 -> 4 | C7: =滚轴与赔付!C33+滚轴与赔付!C$30 -> 6 | D7: =滚轴与赔付!D33+滚轴与赔付!D$30 -> 5 | E7: =滚轴与赔付!E33+滚轴与赔付!E$30 -> 5 | F7: =滚轴与赔付!F33+滚轴与赔付!F$30 -> 5 | G7: =滚轴与赔付!$E$25-E7 -> 15 | H7: =滚轴与赔付!$F$25-F7 -> 15 | I7: =滚轴与赔付!$F$25 -> 20 | J7: =B7*C7*D7*E7*F7 -> 3000 | K7: =B7*C7*D7*E7*H7 -> 9000 | L7: =B7*C7*D7*G7*I7 -> 36000 | M7: =VLOOKUP($A7,滚轴与赔付!$A$41:$D$45,4,FALSE()) -> 75 | N7: =VLOOKUP($A7,滚轴与赔付!$A$41:$D$45,3,FALSE()) -> 20 | O7: =VLOOKUP($A7,滚轴与赔付!$A$41:$D$45,2,FALSE()) -> 5 | P7: =(J7*M7+K7*N7+L7*O7)/滚轴与赔付!$H$25 -> 0.1828125
A8: 10 | B8: =滚轴与赔付!B34+滚轴与赔付!B$30 -> 5 | C8: =滚轴与赔付!C34+滚轴与赔付!C$30 -> 4 | D8: =滚轴与赔付!D34+滚轴与赔付!D$30 -> 5 | E8: =滚轴与赔付!E34+滚轴与赔付!E$30 -> 5 | F8: =滚轴与赔付!F34+滚轴与赔付!F$30 -> 5 | G8: =滚轴与赔付!$E$25-E8 -> 15 | H8: =滚轴与赔付!$F$25-F8 -> 15 | I8: =滚轴与赔付!$F$25 -> 20 | J8: =B8*C8*D8*E8*F8 -> 2500 | K8: =B8*C8*D8*E8*H8 -> 7500 | L8: =B8*C8*D8*G8*I8 -> 30000 | M8: =VLOOKUP($A8,滚轴与赔付!$A$41:$D$45,4,FALSE()) -> 75 | N8: =VLOOKUP($A8,滚轴与赔付!$A$41:$D$45,3,FALSE()) -> 20 | O8: =VLOOKUP($A8,滚轴与赔付!$A$41:$D$45,2,FALSE()) -> 5 | P8: =(J8*M8+K8*N8+L8*O8)/滚轴与赔付!$H$25 -> 0.15234375
A9: 9 | B9: =滚轴与赔付!B35+滚轴与赔付!B$30 -> 6 | C9: =滚轴与赔付!C35+滚轴与赔付!C$30 -> 5 | D9: =滚轴与赔付!D35+滚轴与赔付!D$30 -> 5 | E9: =滚轴与赔付!E35+滚轴与赔付!E$30 -> 5 | F9: =滚轴与赔付!F35+滚轴与赔付!F$30 -> 5 | G9: =滚轴与赔付!$E$25-E9 -> 15 | H9: =滚轴与赔付!$F$25-F9 -> 15 | I9: =滚轴与赔付!$F$25 -> 20 | J9: =B9*C9*D9*E9*F9 -> 3750 | K9: =B9*C9*D9*E9*H9 -> 11250 | L9: =B9*C9*D9*G9*I9 -> 45000 | M9: =VLOOKUP($A9,滚轴与赔付!$A$41:$D$45,4,FALSE()) -> 50 | N9: =VLOOKUP($A9,滚轴与赔付!$A$41:$D$45,3,FALSE()) -> 10 | O9: =VLOOKUP($A9,滚轴与赔付!$A$41:$D$45,2,FALSE()) -> 5 | P9: =(J9*M9+K9*N9+L9*O9)/滚轴与赔付!$H$25 -> 0.1640625
A10: 合计 | J10: =SUM(J5:J9) -> 10274 | K10: =SUM(K5:K9) -> 31846 | L10: =SUM(L5:L9) -> 131480 | M10: → 单线 RTP | P10: =SUM(P5:P9) -> 0.59681875
A12: 【由单线结果读出的指标】
A13: 单线中奖率（至少一条 3 连及以上） | D13: =(J10+K10+L10)/滚轴与赔付!$H$25 -> 0.05425 | E13: ← 5 条线各自的概率，见下页「可选线」
A14: 单线 RTP | D14: =P10 -> 0.59681875
A15: 单线平均中奖金额（倍注）= RTP ÷ 中奖率 | D15: =P10/D13 -> 11.001267
A16: 其中 Scatter 赔付另计（见免费篇 / Part II），此处只算图案连线 | D16: 示例：单线 RTP 59.68%，与《Part II》主游戏连线 RTP 完全一致
A18: 【5 条线的 RTP 汇总】对称滚轴下各线统计相同
A19: 线 | B19: 轮1 | C19: 轮2 | D19: 轮3 | E19: 轮4 | F19: 轮5 | G19: 单线 RTP | H19: 投注(倍线注) | I19: 返还(倍线注) | J19: 总 RTP
A20: Line1 | B20: =滚轴与赔付!B50 -> 1 | C20: =滚轴与赔付!C50 -> 1 | D20: =滚轴与赔付!D50 -> 1 | E20: =滚轴与赔付!E50 -> 1 | F20: =滚轴与赔付!F50 -> 1 | G20: =$P$10 -> 0.59681875 | H20: =1 -> 1 | I20: =G20*H20 -> 0.59681875 | J20: =I20/H20 -> 0.59681875
A21: Line2 | B21: =滚轴与赔付!B51 -> 2 | C21: =滚轴与赔付!C51 -> 2 | D21: =滚轴与赔付!D51 -> 2 | E21: =滚轴与赔付!E51 -> 2 | F21: =滚轴与赔付!F51 -> 2 | G21: =$P$10 -> 0.59681875 | H21: =1 -> 1 | I21: =G21*H21 -> 0.59681875 | J21: =I21/H21 -> 0.59681875
A22: Line3 | B22: =滚轴与赔付!B52 -> 3 | C22: =滚轴与赔付!C52 -> 3 | D22: =滚轴与赔付!D52 -> 3 | E22: =滚轴与赔付!E52 -> 3 | F22: =滚轴与赔付!F52 -> 3 | G22: =$P$10 -> 0.59681875 | H22: =1 -> 1 | I22: =G22*H22 -> 0.59681875 | J22: =I22/H22 -> 0.59681875
A23: Line4 | B23: =滚轴与赔付!B53 -> 1 | C23: =滚轴与赔付!C53 -> 2 | D23: =滚轴与赔付!D53 -> 3 | E23: =滚轴与赔付!E53 -> 2 | F23: =滚轴与赔付!F53 -> 1 | G23: =$P$10 -> 0.59681875 | H23: =1 -> 1 | I23: =G23*H23 -> 0.59681875 | J23: =I23/H23 -> 0.59681875
A24: Line5 | B24: =滚轴与赔付!B54 -> 3 | C24: =滚轴与赔付!C54 -> 2 | D24: =滚轴与赔付!D54 -> 1 | E24: =滚轴与赔付!E54 -> 2 | F24: =滚轴与赔付!F54 -> 3 | G24: =$P$10 -> 0.59681875 | H24: =1 -> 1 | I24: =G24*H24 -> 0.59681875 | J24: =I24/H24 -> 0.59681875
A26: 结论：只要每列的滚轴分布不随「行」变化（环绕带就是如此），每条线的单线 RTP 完全相同。
A27: 因此——加线不会改变 RTP，只会改变「单次旋转总投注」与「中奖率 / 波动」。这正是有线段位 / 可选线段位的数值基础。

Sheet 线注与可选线
A1: 线注换算 与「可选线」对中奖率 / RTP 的影响
A3: 【线注换算】
A4: 线数 L | B4: 5
A5: 单次旋转总投注（线注计） | B5: 5
A6: → 每条线投注（线注） | B6: =B5/B4 -> 1
A7: 记账比例 P（1 个线注 = P 个记账单位） | B7: 10000
A8: → 单次旋转记账总投注 | B8: =B5*B7 -> 50000
A9: → 每条线记账投注 | B9: =B8/B4 -> 10000
A10: 原文：设计者会设定一个固定比例以避免出现除不尽的小数 —— 将比例设为 10000 时，10000 总投注对应的线注就是 1。
A12: 【可选线：玩家只买 n 条线】
A13: 购买线数 n | B13: 单次总投注(线注) | C13: 单线中奖率 p1 | D13: 至少中一条线的概率 | E13: 单次总返还(线注) | F13: 总 RTP | G13: 每转期望返还
A14: 1 | B14: =A14*$B$6 -> 1 | C14: =线型与RTP!$D$13 -> 0.05425 | D14: =1-(1-C14)^A14 -> 0.05425 | E14: =B14*线型与RTP!$P$10 -> 0.59681875 | F14: =线型与RTP!$P$10 -> 0.59681875 | G14: =B14*F14 -> 0.59681875
A15: 2 | B15: =A15*$B$6 -> 2 | C15: =线型与RTP!$D$13 -> 0.05425 | D15: =1-(1-C15)^A15 -> 0.10555694 | E15: =B15*线型与RTP!$P$10 -> 1.1936375 | F15: =线型与RTP!$P$10 -> 0.59681875 | G15: =B15*F15 -> 1.1936375
A16: 3 | B16: =A16*$B$6 -> 3 | C16: =线型与RTP!$D$13 -> 0.05425 | D16: =1-(1-C16)^A16 -> 0.15408047 | E16: =B16*线型与RTP!$P$10 -> 1.7904563 | F16: =线型与RTP!$P$10 -> 0.59681875 | G16: =B16*F16 -> 1.7904563
A17: 4 | B17: =A17*$B$6 -> 4 | C17: =线型与RTP!$D$13 -> 0.05425 | D17: =1-(1-C17)^A17 -> 0.19997161 | E17: =B17*线型与RTP!$P$10 -> 2.387275 | F17: =线型与RTP!$P$10 -> 0.59681875 | G17: =B17*F17 -> 2.387275
A18: 5 | B18: =A18*$B$6 -> 5 | C18: =线型与RTP!$D$13 -> 0.05425 | D18: =1-(1-C18)^A18 -> 0.24337315 | E18: =B18*线型与RTP!$P$10 -> 2.9840937 | F18: =线型与RTP!$P$10 -> 0.59681875 | G18: =B18*F18 -> 2.9840937
A20: 注：总返还 = 总投注 × 单线 RTP（因为每条线的期望完全一样），故 RTP 恒等于单线 RTP。
A21: 选线越少 → 单次下注越少、中奖率越低；选线越多 → 中奖更频繁但单次下注更大。RTP 不变。

Sheet 满线Ways
A1: 满线（Ways）与有线（Lines）的关系
A3: 【ways 数与滚轴结构】
A4: 规格 | B4: 每列可见格 | C4: 列数 | D4: ways 数 = 可见格^列数 | E4: 说明
A5: 3 | B5: 3 | C5: 5 | D5: =B5^C5 -> 243 | E5: 最经典的满线规格
A6: 4 | B6: 4 | C6: 5 | D6: =B6^C6 -> 1024
A7: 5 | B7: 5 | C7: 5 | D7: =B7^C7 -> 3125
A8: 3 | B8: 3 | C8: 3 | D8: =B8^C8 -> 27
A9: 4 | B9: 4 | C9: 3 | D9: =B9^C9 -> 64
A11: 【每列可见匹配格数 → ways】
A12: 举例：某符号在某列 20 停转轮里出现 c 次、WILD 出现 w 次；窗口 3 格
A13: 每列期望匹配格数 e = 3 × (c + w) ÷ N | D13: =3*(1+1)/20 -> 0.3
A14: 5 | D14: =D13^5 -> 0.00243
A15: 说明：满线的命中条件放宽为「每列至少有 1 格是目标符号（或 WILD）」，ways 数 = 各列匹配格数的乘积。因此满线中奖率远高于有线，波动更低，但每条 ways 的赔付倍数要相应下调，RTP 才守得住。
A17: 【有线 vs 满线 的对比】
A18: 对比项 | B18: 有线（Lines） | C18: 满线（Ways）
A19: 中奖判定 | B19: 同图案自第 1 轴起，沿固定 payline 连续 | C19: 同图案自第 1 轴起，每列任一格命中即算
A20: 组合数量 | B20: 等于线数（本簿示例 5 条） | C20: 等于 Π 每列可见格数（3×5 → 243）
A21: 线数是否影响 RTP | B21: 不影响（每条线期望相同） | C21: 不影响（ways 数只放大投注结构）
A22: 中奖率 | B22: 较低（本簿单线 5.43%） | C22: 较高（每列 3 格任一匹配）
A23: 波动 | B23: 较高 | C23: 较低，需要下调单条 ways 的赔付倍数
A24: 界面呈现 | B24: 常展示具体中奖线路图 | C24: 因组合太多，不展示路径图，只声明线数
A26: 原文：满线在游戏规则内不会展示中奖线路图，但会声明线数；看到线数与滚轴一算能对应，就是满线。

Sheet 易错点-窗口环绕
A1: 易错点：滚轴是「环绕带」，把窗口限制在 1..N−2 会造成边缘差
A3: 【正确口径】环绕带
A4: 窗口可停在该列的 N 个位置（含跨过末尾回卷）
A5: 于是「行 1」「行 2」「行 3」看到的格子都遍历整条带
A6: ⇒ 行 1 / 行 2 / 行 3 的符号计数 = 该列整体计数（完全相同）
A8: 【以轮1 为例：两种口径的计数对照】
A9: 符号 | B9: 环绕（行1=行2=行3） | C9: 不环绕·行1 | D9: 不环绕·行2 | E9: 不环绕·行3 | F9: 说明
A10: K | B10: =COUNTIF(滚轴与赔付!$B$5:$B$24,$A10) -> 1 | C10: =COUNTIF(滚轴与赔付!$B$5:$B$22,$A10) -> 1 | D10: =COUNTIF(滚轴与赔付!$B$6:$B$23,$A10) -> 0 | E10: =COUNTIF(滚轴与赔付!$B$7:$B$24,$A10) -> 0
A11: Q | B11: =COUNTIF(滚轴与赔付!$B$5:$B$24,$A11) -> 3 | C11: =COUNTIF(滚轴与赔付!$B$5:$B$22,$A11) -> 3 | D11: =COUNTIF(滚轴与赔付!$B$6:$B$23,$A11) -> 3 | E11: =COUNTIF(滚轴与赔付!$B$7:$B$24,$A11) -> 2
A12: J | B12: =COUNTIF(滚轴与赔付!$B$5:$B$24,$A12) -> 4 | C12: =COUNTIF(滚轴与赔付!$B$5:$B$22,$A12) -> 4 | D12: =COUNTIF(滚轴与赔付!$B$6:$B$23,$A12) -> 4 | E12: =COUNTIF(滚轴与赔付!$B$7:$B$24,$A12) -> 4
A13: 10 | B13: =COUNTIF(滚轴与赔付!$B$5:$B$24,$A13) -> 5 | C13: =COUNTIF(滚轴与赔付!$B$5:$B$22,$A13) -> 5 | D13: =COUNTIF(滚轴与赔付!$B$6:$B$23,$A13) -> 5 | E13: =COUNTIF(滚轴与赔付!$B$7:$B$24,$A13) -> 5
A14: 9 | B14: =COUNTIF(滚轴与赔付!$B$5:$B$24,$A14) -> 6 | C14: =COUNTIF(滚轴与赔付!$B$5:$B$22,$A14) -> 5 | D14: =COUNTIF(滚轴与赔付!$B$6:$B$23,$A14) -> 6 | E14: =COUNTIF(滚轴与赔付!$B$7:$B$24,$A14) -> 6
A15: 不环绕口径下，行 1 只能看到位置 1..18，行 2 只能看到 2..19，行 3 只能看到 3..20，于是三个行的计数出现边缘差；这会让「上/中/下」三条线的 RTP 不再相等，从而把一个对称游戏算成不对称。
A17: 【另一个常见坑：WILD 的行计数】
A18: WILD 也必须按「该列整体计数」进入 mᵢ，而不是只算某一行
A19: 若漏算 WILD，单线 RTP 会明显偏低（见下）
A20: 含 WILD（本簿口径）单线 RTP | B20: =线型与RTP!$P$10 -> 0.59681875
A21: 不含 WILD 的单线 RTP（对照） | B21: =0.3140109375 -> 0.31401094
A22: 差额（WILD 带来的连线收益） | B22: =B20-B21 -> 0.28280781
A24: 对照值 31.40% 的算法：把每个符号的 mᵢ 只取「该符号自身计数」（W=0），其余步骤与「线型与RTP」页完全相同。该口径也可在 WILD 篇中直接调用。
